Workbook

Sheet Start
B1: Finanzplaner 2027
B2: Haushaltsbuch · Budget · Sparziele · Schulden-Plan
B4: Einstellungen
B6: Jahr | C6: 2027
B7: Kontostand am 01.01. (€) | C7: 0
B9: Legende
B10: Gelbe Felder | C10: Hier trägst du etwas ein.
B11: Weiße Felder | C11: Rechnen automatisch – bitte nicht überschreiben.
B13: So legst du los (10 Minuten)
B14: 1. Einstellungen | C14: Trage oben das Jahr und deinen Kontostand am 1. Januar ein.
B15: 2. Kategorien | C15: Passe die Kategorien an und lege für jede ein Monatsbudget fest.
B16: 3. Buchungen | C16: Trage jede Einnahme und Ausgabe ein: Datum, Kategorie (Auswahlliste), Betrag. Beträge immer positiv – die Kategorie entscheidet, ob Einnahme oder Ausgabe.
B17: 4. Monatsübersicht | C17: Zeigt automatisch jeden Monat pro Kategorie. Rot = Monatsbudget überschritten.
B18: 5. Dashboard | C18: Dein Jahr auf einen Blick: Einnahmen, Ausgaben, Sparquote, größte Ausgaben.
B19: 6. Sparziele & Schulden | C19: Rechnet aus, wann du dein Ziel erreichst bzw. schuldenfrei bist.
B21: Tipp | C21: 10 Minuten pro Woche reichen. Trag am besten jeden Sonntag die Buchungen der Woche nach – nach einem Monat weißt du genau, wohin dein Geld fließt.
B22: Wichtig | C22: Wenn du eine Kategorie umbenennst, ändere sie auch in deinen bisherigen Buchungen – sonst werden diese nicht mehr mitgezählt (Spalte „Art“ zeigt dann „unbekannte Kategorie“).
B24: Funktioniert in Microsoft Excel, Google Sheets und LibreOffice.

Sheet Dashboard
A1: ="Dein Finanzjahr "&Start!C6 -> Dein Finanzjahr 2027
A2: Alles hier rechnet automatisch aus deinen Buchungen.
B4: EINNAHMEN | D4: AUSGABEN | F4: ÜBERSCHUSS | H4: SPARQUOTE | J4: KONTOSTAND AKTUELL
B5: =Monatsübersicht!O14 -> 2100 | D5: =Monatsübersicht!O42 -> 0 | F5: =Monatsübersicht!O44 -> 2100 | H5: =IF(Monatsübersicht!O14=0,0,Monatsübersicht!O44/Monatsübersicht!O14) -> 1 | J5: =Start!C7+Monatsübersicht!O44 -> 2100
B7: Ø EINNAHMEN / MONAT | D7: Ø AUSGABEN / MONAT | F7: Ø ÜBERSCHUSS / MONAT | H7: MONATE ERFASST | J7: KATEGORIEN ÜBER BUDGET
B8: =Monatsübersicht!O14/MAX(1,Monatsübersicht!B48) -> 2100 | D8: =Monatsübersicht!O42/MAX(1,Monatsübersicht!B48) -> 0 | F8: =Monatsübersicht!O44/MAX(1,Monatsübersicht!B48) -> 2100 | H8: =Monatsübersicht!B48 -> 1 | J8: =COUNTIF(Monatsübersicht!R17:R41,"<0") -> 0
B11: Monatsverlauf
B12: Monat | C12: Einnahmen | D12: Ausgaben | E12: Überschuss
B13: Jan | C13: =Monatsübersicht!C14 -> 2100 | D13: =Monatsübersicht!C42 -> 0 | E13: =Monatsübersicht!C44 -> 2100
B14: Feb | C14: =Monatsübersicht!D14 -> 0 | D14: =Monatsübersicht!D42 -> 0 | E14: =Monatsübersicht!D44 -> 0
B15: Mär | C15: =Monatsübersicht!E14 -> 0 | D15: =Monatsübersicht!E42 -> 0 | E15: =Monatsübersicht!E44 -> 0
B16: Apr | C16: =Monatsübersicht!F14 -> 0 | D16: =Monatsübersicht!F42 -> 0 | E16: =Monatsübersicht!F44 -> 0
B17: Mai | C17: =Monatsübersicht!G14 -> 0 | D17: =Monatsübersicht!G42 -> 0 | E17: =Monatsübersicht!G44 -> 0
B18: Jun | C18: =Monatsübersicht!H14 -> 0 | D18: =Monatsübersicht!H42 -> 0 | E18: =Monatsübersicht!H44 -> 0
B19: Jul | C19: =Monatsübersicht!I14 -> 0 | D19: =Monatsübersicht!I42 -> 0 | E19: =Monatsübersicht!I44 -> 0
B20: Aug | C20: =Monatsübersicht!J14 -> 0 | D20: =Monatsübersicht!J42 -> 0 | E20: =Monatsübersicht!J44 -> 0
B21: Sep | C21: =Monatsübersicht!K14 -> 0 | D21: =Monatsübersicht!K42 -> 0 | E21: =Monatsübersicht!K44 -> 0
B22: Okt | C22: =Monatsübersicht!L14 -> 0 | D22: =Monatsübersicht!L42 -> 0 | E22: =Monatsübersicht!L44 -> 0
B23: Nov | C23: =Monatsübersicht!M14 -> 0 | D23: =Monatsübersicht!M42 -> 0 | E23: =Monatsübersicht!M44 -> 0
B24: Dez | C24: =Monatsübersicht!N14 -> 0 | D24: =Monatsübersicht!N42 -> 0 | E24: =Monatsübersicht!N44 -> 0
B27: Deine größten Ausgaben
B28: Kategorie | D28: Summe | E28: Anteil
B29: =IF(INDEX(Monatsübersicht!$O$17:$O$41,MATCH(LARGE(Monatsübersicht!$S$17:$S$41,1),Monatsübersicht!$S$17:$S$41,0))<=0,"",INDEX(Monatsübersicht!$A$17:$A$41,MATCH(LARGE(Monatsübersicht!$S$17:$S$41,1),Monatsübersicht!$S$17:$S$41,0))) | D29: =MAX(0,INDEX(Monatsübersicht!$O$17:$O$41,MATCH(LARGE(Monatsübersicht!$S$17:$S$41,1),Monatsübersicht!$S$17:$S$41,0))) -> 0 | E29: =IF(Monatsübersicht!O42=0,0,D29/Monatsübersicht!O42) -> 0
B30: =IF(INDEX(Monatsübersicht!$O$17:$O$41,MATCH(LARGE(Monatsübersicht!$S$17:$S$41,2),Monatsübersicht!$S$17:$S$41,0))<=0,"",INDEX(Monatsübersicht!$A$17:$A$41,MATCH(LARGE(Monatsübersicht!$S$17:$S$41,2),Monatsübersicht!$S$17:$S$41,0))) | D30: =MAX(0,INDEX(Monatsübersicht!$O$17:$O$41,MATCH(LARGE(Monatsübersicht!$S$17:$S$41,2),Monatsübersicht!$S$17:$S$41,0))) -> 0 | E30: =IF(Monatsübersicht!O42=0,0,D30/Monatsübersicht!O42) -> 0
B31: =IF(INDEX(Monatsübersicht!$O$17:$O$41,MATCH(LARGE(Monatsübersicht!$S$17:$S$41,3),Monatsübersicht!$S$17:$S$41,0))<=0,"",INDEX(Monatsübersicht!$A$17:$A$41,MATCH(LARGE(Monatsübersicht!$S$17:$S$41,3),Monatsübersicht!$S$17:$S$41,0))) | D31: =MAX(0,INDEX(Monatsübersicht!$O$17:$O$41,MATCH(LARGE(Monatsübersicht!$S$17:$S$41,3),Monatsübersicht!$S$17:$S$41,0))) -> 0 | E31: =IF(Monatsübersicht!O42=0,0,D31/Monatsübersicht!O42) -> 0
B32: =IF(INDEX(Monatsübersicht!$O$17:$O$41,MATCH(LARGE(Monatsübersicht!$S$17:$S$41,4),Monatsübersicht!$S$17:$S$41,0))<=0,"",INDEX(Monatsübersicht!$A$17:$A$41,MATCH(LARGE(Monatsübersicht!$S$17:$S$41,4),Monatsübersicht!$S$17:$S$41,0))) | D32: =MAX(0,INDEX(Monatsübersicht!$O$17:$O$41,MATCH(LARGE(Monatsübersicht!$S$17:$S$41,4),Monatsübersicht!$S$17:$S$41,0))) -> 0 | E32: =IF(Monatsübersicht!O42=0,0,D32/Monatsübersicht!O42) -> 0
B33: =IF(INDEX(Monatsübersicht!$O$17:$O$41,MATCH(LARGE(Monatsübersicht!$S$17:$S$41,5),Monatsübersicht!$S$17:$S$41,0))<=0,"",INDEX(Monatsübersicht!$A$17:$A$41,MATCH(LARGE(Monatsübersicht!$S$17:$S$41,5),Monatsübersicht!$S$17:$S$41,0))) | D33: =MAX(0,INDEX(Monatsübersicht!$O$17:$O$41,MATCH(LARGE(Monatsübersicht!$S$17:$S$41,5),Monatsübersicht!$S$17:$S$41,0))) -> 0 | E33: =IF(Monatsübersicht!O42=0,0,D33/Monatsübersicht!O42) -> 0
B34: =IF(INDEX(Monatsübersicht!$O$17:$O$41,MATCH(LARGE(Monatsübersicht!$S$17:$S$41,6),Monatsübersicht!$S$17:$S$41,0))<=0,"",INDEX(Monatsübersicht!$A$17:$A$41,MATCH(LARGE(Monatsübersicht!$S$17:$S$41,6),Monatsübersicht!$S$17:$S$41,0))) | D34: =MAX(0,INDEX(Monatsübersicht!$O$17:$O$41,MATCH(LARGE(Monatsübersicht!$S$17:$S$41,6),Monatsübersicht!$S$17:$S$41,0))) -> 0 | E34: =IF(Monatsübersicht!O42=0,0,D34/Monatsübersicht!O42) -> 0
B35: =IF(INDEX(Monatsübersicht!$O$17:$O$41,MATCH(LARGE(Monatsübersicht!$S$17:$S$41,7),Monatsübersicht!$S$17:$S$41,0))<=0,"",INDEX(Monatsübersicht!$A$17:$A$41,MATCH(LARGE(Monatsübersicht!$S$17:$S$41,7),Monatsübersicht!$S$17:$S$41,0))) | D35: =MAX(0,INDEX(Monatsübersicht!$O$17:$O$41,MATCH(LARGE(Monatsübersicht!$S$17:$S$41,7),Monatsübersicht!$S$17:$S$41,0))) -> 0 | E35: =IF(Monatsübersicht!O42=0,0,D35/Monatsübersicht!O42) -> 0
B36: =IF(INDEX(Monatsübersicht!$O$17:$O$41,MATCH(LARGE(Monatsübersicht!$S$17:$S$41,8),Monatsübersicht!$S$17:$S$41,0))<=0,"",INDEX(Monatsübersicht!$A$17:$A$41,MATCH(LARGE(Monatsübersicht!$S$17:$S$41,8),Monatsübersicht!$S$17:$S$41,0))) | D36: =MAX(0,INDEX(Monatsübersicht!$O$17:$O$41,MATCH(LARGE(Monatsübersicht!$S$17:$S$41,8),Monatsübersicht!$S$17:$S$41,0))) -> 0 | E36: =IF(Monatsübersicht!O42=0,0,D36/Monatsübersicht!O42) -> 0

Sheet Buchungen
A1: Buchungen
A2: Jede Einnahme und Ausgabe in eine Zeile. Beträge immer positiv – die Kategorie bestimmt, ob es eine Einnahme oder Ausgabe ist.
A4: Datum | B4: Kategorie | C4: Beschreibung | D4: Betrag (€) | E4: Art (automatisch)
A5: 46388 | B5: Gehalt / Lohn | C5: Beispiel – diese Zeile einfach überschreiben | D5: 2100 | E5: =IF(B5="","",IFERROR(INDEX(Kategorien!$B$5:$B$37,MATCH(B5,Kategorien!$A$5:$A$37,0)),"unbekannte Kategorie")) -> Einnahme
E6: =IF(B6="","",IFERROR(INDEX(Kategorien!$B$5:$B$37,MATCH(B6,Kategorien!$A$5:$A$37,0)),"unbekannte Kategorie"))
E7: =IF(B7="","",IFERROR(INDEX(Kategorien!$B$5:$B$37,MATCH(B7,Kategorien!$A$5:$A$37,0)),"unbekannte Kategorie"))
E8: =IF(B8="","",IFERROR(INDEX(Kategorien!$B$5:$B$37,MATCH(B8,Kategorien!$A$5:$A$37,0)),"unbekannte Kategorie"))
E9: =IF(B9="","",IFERROR(INDEX(Kategorien!$B$5:$B$37,MATCH(B9,Kategorien!$A$5:$A$37,0)),"unbekannte Kategorie"))
E10: =IF(B10="","",IFERROR(INDEX(Kategorien!$B$5:$B$37,MATCH(B10,Kategorien!$A$5:$A$37,0)),"unbekannte Kategorie"))
E11: =IF(B11="","",IFERROR(INDEX(Kategorien!$B$5:$B$37,MATCH(B11,Kategorien!$A$5:$A$37,0)),"unbekannte Kategorie"))
E12: =IF(B12="","",IFERROR(INDEX(Kategorien!$B$5:$B$37,MATCH(B12,Kategorien!$A$5:$A$37,0)),"unbekannte Kategorie"))
E13: =IF(B13="","",IFERROR(INDEX(Kategorien!$B$5:$B$37,MATCH(B13,Kategorien!$A$5:$A$37,0)),"unbekannte Kategorie"))
E14: =IF(B14="","",IFERROR(INDEX(Kategorien!$B$5:$B$37,MATCH(B14,Kategorien!$A$5:$A$37,0)),"unbekannte Kategorie"))
E15: =IF(B15="","",IFERROR(INDEX(Kategorien!$B$5:$B$37,MATCH(B15,Kategorien!$A$5:$A$37,0)),"unbekannte Kategorie"))
E16: =IF(B16="","",IFERROR(INDEX(Kategorien!$B$5:$B$37,MATCH(B16,Kategorien!$A$5:$A$37,0)),"unbekannte Kategorie"))
E17: =IF(B17="","",IFERROR(INDEX(Kategorien!$B$5:$B$37,MATCH(B17,Kategorien!$A$5:$A$37,0)),"unbekannte Kategorie"))
... E1004: =IF(B1004="","",IFERROR(INDEX(Kategorien!$B$5:$B$37,MATCH(B1004,Kategorien!$A$5:$A$37,0)),"unbekannte Kategorie"))

Sheet Kategorien
A1: Kategorien & Monatsbudget
A2: Namen frei änderbar. Leere Zeilen kannst du für eigene Kategorien nutzen.
A4: Kategorie | B4: Art | C4: Monatsbudget (€) | E4: Hinweise
A5: Gehalt / Lohn | B5: Einnahme | E5: Zeilen 5–12: Einnahmen (max. 8 Kategorien)
A6: Nebenjob | B6: Einnahme | E6: Zeilen 13–37: Ausgaben (max. 25 Kategorien)
A7: Verkäufe (Kleinanzeigen etc.) | B7: Einnahme | E7: Das Monatsbudget ist dein Plan. Die Monatsübersicht färbt Monate rot,
A8: Sonstige Einnahmen | B8: Einnahme | E8: in denen du eine Ausgaben-Kategorie überzogen hast.
B9: Einnahme | E9: Faustregel 50/30/20: 50 % Fixkosten, 30 % Freizeit & Wünsche, 20 % Sparen.
B10: Einnahme
B11: Einnahme
B12: Einnahme
A13: Miete & Nebenkosten | B13: Ausgabe
A14: Strom & Internet | B14: Ausgabe
A15: Lebensmittel | B15: Ausgabe
A16: Handy & Abos | B16: Ausgabe
A17: Mobilität (Auto/ÖPNV) | B17: Ausgabe
A18: Versicherungen | B18: Ausgabe
A19: Freizeit & Ausgehen | B19: Ausgabe
A20: Kleidung | B20: Ausgabe
A21: Gesundheit & Drogerie | B21: Ausgabe
A22: Geschenke | B22: Ausgabe
A23: Urlaub | B23: Ausgabe
A24: Sonstiges | B24: Ausgabe
B25: Ausgabe
B26: Ausgabe
B27: Ausgabe
B28: Ausgabe
B29: Ausgabe
B30: Ausgabe
B31: Ausgabe
B32: Ausgabe
B33: Ausgabe
B34: Ausgabe
B35: Ausgabe
B36: Ausgabe
B37: Ausgabe

Sheet Monatsübersicht
A1: ="Monatsübersicht "&Start!C6 -> Monatsübersicht 2027
A2: Rechnet automatisch aus deinen Buchungen. Rot hinterlegt = Monatsbudget überschritten.
C3: 1 | D3: 2 | E3: 3 | F3: 4 | G3: 5 | H3: 6 | I3: 7 | J3: 8 | K3: 9 | L3: 10 | M3: 11 | N3: 12
A4: Kategorie | B4: Budget / Monat | C4: Jan | D4: Feb | E4: Mär | F4: Apr | G4: Mai | H4: Jun | I4: Jul | J4: Aug | K4: Sep | L4: Okt | M4: Nov | N4: Dez | O4: Summe | P4: Ø / Monat | Q4: Budget bisher | R4: Abweichung (+ = gut)
A5: EINNAHMEN
A6: =IF(Kategorien!A5="","",Kategorien!A5) -> Gehalt / Lohn | B6: =IF($A6="",0,N(Kategorien!C5)) -> 0 | C6: =IF($A6="",0,SUMIFS(Buchungen!$D$5:$D$1004,Buchungen!$B$5:$B$1004,$A6,Buchungen!$A$5:$A$1004,">="&DATE(Start!$C$6,C$3,1),Buchungen!$A$5:$A$1004,"<"&DATE(Start!$C$6,C$3+1,1))) -> 2100 | D6: =IF($A6="",0,SUMIFS(Buchungen!$D$5:$D$1004,Buchungen!$B$5:$B$1004,$A6,Buchungen!$A$5:$A$1004,">="&DATE(Start!$C$6,D$3,1),Buchungen!$A$5:$A$1004,"<"&DATE(Start!$C$6,D$3+1,1))) -> 0 | E6: =IF($A6="",0,SUMIFS(Buchungen!$D$5:$D$1004,Buchungen!$B$5:$B$1004,$A6,Buchungen!$A$5:$A$1004,">="&DATE(Start!$C$6,E$3,1),Buchungen!$A$5:$A$1004,"<"&DATE(Start!$C$6,E$3+1,1))) -> 0 | F6: =IF($A6="",0,SUMIFS(Buchungen!$D$5:$D$1004,Buchungen!$B$5:$B$1004,$A6,Buchungen!$A$5:$A$1004,">="&DATE(Start!$C$6,F$3,1),Buchungen!$A$5:$A$1004,"<"&DATE(Start!$C$6,F$3+1,1))) -> 0 | G6: =IF($A6="",0,SUMIFS(Buchungen!$D$5:$D$1004,Buchungen!$B$5:$B$1004,$A6,Buchungen!$A$5:$A$1004,">="&DATE(Start!$C$6,G$3,1),Buchungen!$A$5:$A$1004,"<"&DATE(Start!$C$6,G$3+1,1))) -> 0 | H6: =IF($A6="",0,SUMIFS(Buchungen!$D$5:$D$1004,Buchungen!$B$5:$B$1004,$A6,Buchungen!$A$5:$A$1004,">="&DATE(Start!$C$6,H$3,1),Buchungen!$A$5:$A$1004,"<"&DATE(Start!$C$6,H$3+1,1))) -> 0 | I6: =IF($A6="",0,SUMIFS(Buchungen!$D$5:$D$1004,Buchungen!$B$5:$B$1004,$A6,Buchungen!$A$5:$A$1004,">="&DATE(Start!$C$6,I$3,1),Buchungen!$A$5:$A$1004,"<"&DATE(Start!$C$6,I$3+1,1))) -> 0 | J6: =IF($A6="",0,SUMIFS(Buchungen!$D$5:$D$1004,Buchungen!$B$5:$B$1004,$A6,Buchungen!$A$5:$A$1004,">="&DATE(Start!$C$6,J$3,1),Buchungen!$A$5:$A$1004,"<"&DATE(Start!$C$6,J$3+1,1))) -> 0 | ... N6: =IF($A6="",0,SUMIFS(Buchungen!$D$5:$D$1004,Buchungen!$B$5:$B$1004,$A6,Buchungen!$A$5:$A$1004,">="&DATE(Start!$C$6,N$3,1),Buchungen!$A$5:$A$1004,"<"&DATE(Start!$C$6,N$3+1,1))) -> 0 | O6: =SUM(C6:N6) -> 2100 | P6: =IF($A6="","",O6/MAX(1,$B$48)) -> 2100 | Q6: =IF(OR($A6="",$B6=0),"",B6*$B$48) | R6: =IF(OR($A6="",$B6=0),"",O6-Q6)
A7: =IF(Kategorien!A6="","",Kategorien!A6) -> Nebenjob | B7: =IF($A7="",0,N(Kategorien!C6)) -> 0 | C7: =IF($A7="",0,SUMIFS(Buchungen!$D$5:$D$1004,Buchungen!$B$5:$B$1004,$A7,Buchungen!$A$5:$A$1004,">="&DATE(Start!$C$6,C$3,1),Buchungen!$A$5:$A$1004,"<"&DATE(Start!$C$6,C$3+1,1))) -> 0 | D7: =IF($A7="",0,SUMIFS(Buchungen!$D$5:$D$1004,Buchungen!$B$5:$B$1004,$A7,Buchungen!$A$5:$A$1004,">="&DATE(Start!$C$6,D$3,1),Buchungen!$A$5:$A$1004,"<"&DATE(Start!$C$6,D$3+1,1))) -> 0 | E7: =IF($A7="",0,SUMIFS(Buchungen!$D$5:$D$1004,Buchungen!$B$5:$B$1004,$A7,Buchungen!$A$5:$A$1004,">="&DATE(Start!$C$6,E$3,1),Buchungen!$A$5:$A$1004,"<"&DATE(Start!$C$6,E$3+1,1))) -> 0 | F7: =IF($A7="",0,SUMIFS(Buchungen!$D$5:$D$1004,Buchungen!$B$5:$B$1004,$A7,Buchungen!$A$5:$A$1004,">="&DATE(Start!$C$6,F$3,1),Buchungen!$A$5:$A$1004,"<"&DATE(Start!$C$6,F$3+1,1))) -> 0 | G7: =IF($A7="",0,SUMIFS(Buchungen!$D$5:$D$1004,Buchungen!$B$5:$B$1004,$A7,Buchungen!$A$5:$A$1004,">="&DATE(Start!$C$6,G$3,1),Buchungen!$A$5:$A$1004,"<"&DATE(Start!$C$6,G$3+1,1))) -> 0 | H7: =IF($A7="",0,SUMIFS(Buchungen!$D$5:$D$1004,Buchungen!$B$5:$B$1004,$A7,Buchungen!$A$5:$A$1004,">="&DATE(Start!$C$6,H$3,1),Buchungen!$A$5:$A$1004,"<"&DATE(Start!$C$6,H$3+1,1))) -> 0 | I7: =IF($A7="",0,SUMIFS(Buchungen!$D$5:$D$1004,Buchungen!$B$5:$B$1004,$A7,Buchungen!$A$5:$A$1004,">="&DATE(Start!$C$6,I$3,1),Buchungen!$A$5:$A$1004,"<"&DATE(Start!$C$6,I$3+1,1))) -> 0 | J7: =IF($A7="",0,SUMIFS(Buchungen!$D$5:$D$1004,Buchungen!$B$5:$B$1004,$A7,Buchungen!$A$5:$A$1004,">="&DATE(Start!$C$6,J$3,1),Buchungen!$A$5:$A$1004,"<"&DATE(Start!$C$6,J$3+1,1))) -> 0 | ... N7: =IF($A7="",0,SUMIFS(Buchungen!$D$5:$D$1004,Buchungen!$B$5:$B$1004,$A7,Buchungen!$A$5:$A$1004,">="&DATE(Start!$C$6,N$3,1),Buchungen!$A$5:$A$1004,"<"&DATE(Start!$C$6,N$3+1,1))) -> 0 | O7: =SUM(C7:N7) -> 0 | P7: =IF($A7="","",O7/MAX(1,$B$48)) -> 0 | Q7: =IF(OR($A7="",$B7=0),"",B7*$B$48) | R7: =IF(OR($A7="",$B7=0),"",O7-Q7)
A8: =IF(Kategorien!A7="","",Kategorien!A7) -> Verkäufe (Kleinanzeigen etc.) | B8: =IF($A8="",0,N(Kategorien!C7)) -> 0 | C8: =IF($A8="",0,SUMIFS(Buchungen!$D$5:$D$1004,Buchungen!$B$5:$B$1004,$A8,Buchungen!$A$5:$A$1004,">="&DATE(Start!$C$6,C$3,1),Buchungen!$A$5:$A$1004,"<"&DATE(Start!$C$6,C$3+1,1))) -> 0 | D8: =IF($A8="",0,SUMIFS(Buchungen!$D$5:$D$1004,Buchungen!$B$5:$B$1004,$A8,Buchungen!$A$5:$A$1004,">="&DATE(Start!$C$6,D$3,1),Buchungen!$A$5:$A$1004,"<"&DATE(Start!$C$6,D$3+1,1))) -> 0 | E8: =IF($A8="",0,SUMIFS(Buchungen!$D$5:$D$1004,Buchungen!$B$5:$B$1004,$A8,Buchungen!$A$5:$A$1004,">="&DATE(Start!$C$6,E$3,1),Buchungen!$A$5:$A$1004,"<"&DATE(Start!$C$6,E$3+1,1))) -> 0 | F8: =IF($A8="",0,SUMIFS(Buchungen!$D$5:$D$1004,Buchungen!$B$5:$B$1004,$A8,Buchungen!$A$5:$A$1004,">="&DATE(Start!$C$6,F$3,1),Buchungen!$A$5:$A$1004,"<"&DATE(Start!$C$6,F$3+1,1))) -> 0 | G8: =IF($A8="",0,SUMIFS(Buchungen!$D$5:$D$1004,Buchungen!$B$5:$B$1004,$A8,Buchungen!$A$5:$A$1004,">="&DATE(Start!$C$6,G$3,1),Buchungen!$A$5:$A$1004,"<"&DATE(Start!$C$6,G$3+1,1))) -> 0 | H8: =IF($A8="",0,SUMIFS(Buchungen!$D$5:$D$1004,Buchungen!$B$5:$B$1004,$A8,Buchungen!$A$5:$A$1004,">="&DATE(Start!$C$6,H$3,1),Buchungen!$A$5:$A$1004,"<"&DATE(Start!$C$6,H$3+1,1))) -> 0 | I8: =IF($A8="",0,SUMIFS(Buchungen!$D$5:$D$1004,Buchungen!$B$5:$B$1004,$A8,Buchungen!$A$5:$A$1004,">="&DATE(Start!$C$6,I$3,1),Buchungen!$A$5:$A$1004,"<"&DATE(Start!$C$6,I$3+1,1))) -> 0 | J8: =IF($A8="",0,SUMIFS(Buchungen!$D$5:$D$1004,Buchungen!$B$5:$B$1004,$A8,Buchungen!$A$5:$A$1004,">="&DATE(Start!$C$6,J$3,1),Buchungen!$A$5:$A$1004,"<"&DATE(Start!$C$6,J$3+1,1))) -> 0 | ... N8: =IF($A8="",0,SUMIFS(Buchungen!$D$5:$D$1004,Buchungen!$B$5:$B$1004,$A8,Buchungen!$A$5:$A$1004,">="&DATE(Start!$C$6,N$3,1),Buchungen!$A$5:$A$1004,"<"&DATE(Start!$C$6,N$3+1,1))) -> 0 | O8: =SUM(C8:N8) -> 0 | P8: =IF($A8="","",O8/MAX(1,$B$48)) -> 0 | Q8: =IF(OR($A8="",$B8=0),"",B8*$B$48) | R8: =IF(OR($A8="",$B8=0),"",O8-Q8)
A9: =IF(Kategorien!A8="","",Kategorien!A8) -> Sonstige Einnahmen | B9: =IF($A9="",0,N(Kategorien!C8)) -> 0 | C9: =IF($A9="",0,SUMIFS(Buchungen!$D$5:$D$1004,Buchungen!$B$5:$B$1004,$A9,Buchungen!$A$5:$A$1004,">="&DATE(Start!$C$6,C$3,1),Buchungen!$A$5:$A$1004,"<"&DATE(Start!$C$6,C$3+1,1))) -> 0 | D9: =IF($A9="",0,SUMIFS(Buchungen!$D$5:$D$1004,Buchungen!$B$5:$B$1004,$A9,Buchungen!$A$5:$A$1004,">="&DATE(Start!$C$6,D$3,1),Buchungen!$A$5:$A$1004,"<"&DATE(Start!$C$6,D$3+1,1))) -> 0 | E9: =IF($A9="",0,SUMIFS(Buchungen!$D$5:$D$1004,Buchungen!$B$5:$B$1004,$A9,Buchungen!$A$5:$A$1004,">="&DATE(Start!$C$6,E$3,1),Buchungen!$A$5:$A$1004,"<"&DATE(Start!$C$6,E$3+1,1))) -> 0 | F9: =IF($A9="",0,SUMIFS(Buchungen!$D$5:$D$1004,Buchungen!$B$5:$B$1004,$A9,Buchungen!$A$5:$A$1004,">="&DATE(Start!$C$6,F$3,1),Buchungen!$A$5:$A$1004,"<"&DATE(Start!$C$6,F$3+1,1))) -> 0 | G9: =IF($A9="",0,SUMIFS(Buchungen!$D$5:$D$1004,Buchungen!$B$5:$B$1004,$A9,Buchungen!$A$5:$A$1004,">="&DATE(Start!$C$6,G$3,1),Buchungen!$A$5:$A$1004,"<"&DATE(Start!$C$6,G$3+1,1))) -> 0 | H9: =IF($A9="",0,SUMIFS(Buchungen!$D$5:$D$1004,Buchungen!$B$5:$B$1004,$A9,Buchungen!$A$5:$A$1004,">="&DATE(Start!$C$6,H$3,1),Buchungen!$A$5:$A$1004,"<"&DATE(Start!$C$6,H$3+1,1))) -> 0 | I9: =IF($A9="",0,SUMIFS(Buchungen!$D$5:$D$1004,Buchungen!$B$5:$B$1004,$A9,Buchungen!$A$5:$A$1004,">="&DATE(Start!$C$6,I$3,1),Buchungen!$A$5:$A$1004,"<"&DATE(Start!$C$6,I$3+1,1))) -> 0 | J9: =IF($A9="",0,SUMIFS(Buchungen!$D$5:$D$1004,Buchungen!$B$5:$B$1004,$A9,Buchungen!$A$5:$A$1004,">="&DATE(Start!$C$6,J$3,1),Buchungen!$A$5:$A$1004,"<"&DATE(Start!$C$6,J$3+1,1))) -> 0 | ... N9: =IF($A9="",0,SUMIFS(Buchungen!$D$5:$D$1004,Buchungen!$B$5:$B$1004,$A9,Buchungen!$A$5:$A$1004,">="&DATE(Start!$C$6,N$3,1),Buchungen!$A$5:$A$1004,"<"&DATE(Start!$C$6,N$3+1,1))) -> 0 | O9: =SUM(C9:N9) -> 0 | P9: =IF($A9="","",O9/MAX(1,$B$48)) -> 0 | Q9: =IF(OR($A9="",$B9=0),"",B9*$B$48) | R9: =IF(OR($A9="",$B9=0),"",O9-Q9)
A10: =IF(Kategorien!A9="","",Kategorien!A9) | B10: =IF($A10="",0,N(Kategorien!C9)) -> 0 | C10: =IF($A10="",0,SUMIFS(Buchungen!$D$5:$D$1004,Buchungen!$B$5:$B$1004,$A10,Buchungen!$A$5:$A$1004,">="&DATE(Start!$C$6,C$3,1),Buchungen!$A$5:$A$1004,"<"&DATE(Start!$C$6,C$3+1,1))) -> 0 | D10: =IF($A10="",0,SUMIFS(Buchungen!$D$5:$D$1004,Buchungen!$B$5:$B$1004,$A10,Buchungen!$A$5:$A$1004,">="&DATE(Start!$C$6,D$3,1),Buchungen!$A$5:$A$1004,"<"&DATE(Start!$C$6,D$3+1,1))) -> 0 | E10: =IF($A10="",0,SUMIFS(Buchungen!$D$5:$D$1004,Buchungen!$B$5:$B$1004,$A10,Buchungen!$A$5:$A$1004,">="&DATE(Start!$C$6,E$3,1),Buchungen!$A$5:$A$1004,"<"&DATE(Start!$C$6,E$3+1,1))) -> 0 | F10: =IF($A10="",0,SUMIFS(Buchungen!$D$5:$D$1004,Buchungen!$B$5:$B$1004,$A10,Buchungen!$A$5:$A$1004,">="&DATE(Start!$C$6,F$3,1),Buchungen!$A$5:$A$1004,"<"&DATE(Start!$C$6,F$3+1,1))) -> 0 | G10: =IF($A10="",0,SUMIFS(Buchungen!$D$5:$D$1004,Buchungen!$B$5:$B$1004,$A10,Buchungen!$A$5:$A$1004,">="&DATE(Start!$C$6,G$3,1),Buchungen!$A$5:$A$1004,"<"&DATE(Start!$C$6,G$3+1,1))) -> 0 | H10: =IF($A10="",0,SUMIFS(Buchungen!$D$5:$D$1004,Buchungen!$B$5:$B$1004,$A10,Buchungen!$A$5:$A$1004,">="&DATE(Start!$C$6,H$3,1),Buchungen!$A$5:$A$1004,"<"&DATE(Start!$C$6,H$3+1,1))) -> 0 | I10: =IF($A10="",0,SUMIFS(Buchungen!$D$5:$D$1004,Buchungen!$B$5:$B$1004,$A10,Buchungen!$A$5:$A$1004,">="&DATE(Start!$C$6,I$3,1),Buchungen!$A$5:$A$1004,"<"&DATE(Start!$C$6,I$3+1,1))) -> 0 | J10: =IF($A10="",0,SUMIFS(Buchungen!$D$5:$D$1004,Buchungen!$B$5:$B$1004,$A10,Buchungen!$A$5:$A$1004,">="&DATE(Start!$C$6,J$3,1),Buchungen!$A$5:$A$1004,"<"&DATE(Start!$C$6,J$3+1,1))) -> 0 | ... N10: =IF($A10="",0,SUMIFS(Buchungen!$D$5:$D$1004,Buchungen!$B$5:$B$1004,$A10,Buchungen!$A$5:$A$1004,">="&DATE(Start!$C$6,N$3,1),Buchungen!$A$5:$A$1004,"<"&DATE(Start!$C$6,N$3+1,1))) -> 0 | O10: =SUM(C10:N10) -> 0 | P10: =IF($A10="","",O10/MAX(1,$B$48)) | Q10: =IF(OR($A10="",$B10=0),"",B10*$B$48) | R10: =IF(OR($A10="",$B10=0),"",O10-Q10)
A11: =IF(Kategorien!A10="","",Kategorien!A10) | B11: =IF($A11="",0,N(Kategorien!C10)) -> 0 | C11: =IF($A11="",0,SUMIFS(Buchungen!$D$5:$D$1004,Buchungen!$B$5:$B$1004,$A11,Buchungen!$A$5:$A$1004,">="&DATE(Start!$C$6,C$3,1),Buchungen!$A$5:$A$1004,"<"&DATE(Start!$C$6,C$3+1,1))) -> 0 | D11: =IF($A11="",0,SUMIFS(Buchungen!$D$5:$D$1004,Buchungen!$B$5:$B$1004,$A11,Buchungen!$A$5:$A$1004,">="&DATE(Start!$C$6,D$3,1),Buchungen!$A$5:$A$1004,"<"&DATE(Start!$C$6,D$3+1,1))) -> 0 | E11: =IF($A11="",0,SUMIFS(Buchungen!$D$5:$D$1004,Buchungen!$B$5:$B$1004,$A11,Buchungen!$A$5:$A$1004,">="&DATE(Start!$C$6,E$3,1),Buchungen!$A$5:$A$1004,"<"&DATE(Start!$C$6,E$3+1,1))) -> 0 | F11: =IF($A11="",0,SUMIFS(Buchungen!$D$5:$D$1004,Buchungen!$B$5:$B$1004,$A11,Buchungen!$A$5:$A$1004,">="&DATE(Start!$C$6,F$3,1),Buchungen!$A$5:$A$1004,"<"&DATE(Start!$C$6,F$3+1,1))) -> 0 | G11: =IF($A11="",0,SUMIFS(Buchungen!$D$5:$D$1004,Buchungen!$B$5:$B$1004,$A11,Buchungen!$A$5:$A$1004,">="&DATE(Start!$C$6,G$3,1),Buchungen!$A$5:$A$1004,"<"&DATE(Start!$C$6,G$3+1,1))) -> 0 | H11: =IF($A11="",0,SUMIFS(Buchungen!$D$5:$D$1004,Buchungen!$B$5:$B$1004,$A11,Buchungen!$A$5:$A$1004,">="&DATE(Start!$C$6,H$3,1),Buchungen!$A$5:$A$1004,"<"&DATE(Start!$C$6,H$3+1,1))) -> 0 | I11: =IF($A11="",0,SUMIFS(Buchungen!$D$5:$D$1004,Buchungen!$B$5:$B$1004,$A11,Buchungen!$A$5:$A$1004,">="&DATE(Start!$C$6,I$3,1),Buchungen!$A$5:$A$1004,"<"&DATE(Start!$C$6,I$3+1,1))) -> 0 | J11: =IF($A11="",0,SUMIFS(Buchungen!$D$5:$D$1004,Buchungen!$B$5:$B$1004,$A11,Buchungen!$A$5:$A$1004,">="&DATE(Start!$C$6,J$3,1),Buchungen!$A$5:$A$1004,"<"&DATE(Start!$C$6,J$3+1,1))) -> 0 | ... N11: =IF($A11="",0,SUMIFS(Buchungen!$D$5:$D$1004,Buchungen!$B$5:$B$1004,$A11,Buchungen!$A$5:$A$1004,">="&DATE(Start!$C$6,N$3,1),Buchungen!$A$5:$A$1004,"<"&DATE(Start!$C$6,N$3+1,1))) -> 0 | O11: =SUM(C11:N11) -> 0 | P11: =IF($A11="","",O11/MAX(1,$B$48)) | Q11: =IF(OR($A11="",$B11=0),"",B11*$B$48) | R11: =IF(OR($A11="",$B11=0),"",O11-Q11)
A12: =IF(Kategorien!A11="","",Kategorien!A11) | B12: =IF($A12="",0,N(Kategorien!C11)) -> 0 | C12: =IF($A12="",0,SUMIFS(Buchungen!$D$5:$D$1004,Buchungen!$B$5:$B$1004,$A12,Buchungen!$A$5:$A$1004,">="&DATE(Start!$C$6,C$3,1),Buchungen!$A$5:$A$1004,"<"&DATE(Start!$C$6,C$3+1,1))) -> 0 | D12: =IF($A12="",0,SUMIFS(Buchungen!$D$5:$D$1004,Buchungen!$B$5:$B$1004,$A12,Buchungen!$A$5:$A$1004,">="&DATE(Start!$C$6,D$3,1),Buchungen!$A$5:$A$1004,"<"&DATE(Start!$C$6,D$3+1,1))) -> 0 | E12: =IF($A12="",0,SUMIFS(Buchungen!$D$5:$D$1004,Buchungen!$B$5:$B$1004,$A12,Buchungen!$A$5:$A$1004,">="&DATE(Start!$C$6,E$3,1),Buchungen!$A$5:$A$1004,"<"&DATE(Start!$C$6,E$3+1,1))) -> 0 | F12: =IF($A12="",0,SUMIFS(Buchungen!$D$5:$D$1004,Buchungen!$B$5:$B$1004,$A12,Buchungen!$A$5:$A$1004,">="&DATE(Start!$C$6,F$3,1),Buchungen!$A$5:$A$1004,"<"&DATE(Start!$C$6,F$3+1,1))) -> 0 | G12: =IF($A12="",0,SUMIFS(Buchungen!$D$5:$D$1004,Buchungen!$B$5:$B$1004,$A12,Buchungen!$A$5:$A$1004,">="&DATE(Start!$C$6,G$3,1),Buchungen!$A$5:$A$1004,"<"&DATE(Start!$C$6,G$3+1,1))) -> 0 | H12: =IF($A12="",0,SUMIFS(Buchungen!$D$5:$D$1004,Buchungen!$B$5:$B$1004,$A12,Buchungen!$A$5:$A$1004,">="&DATE(Start!$C$6,H$3,1),Buchungen!$A$5:$A$1004,"<"&DATE(Start!$C$6,H$3+1,1))) -> 0 | I12: =IF($A12="",0,SUMIFS(Buchungen!$D$5:$D$1004,Buchungen!$B$5:$B$1004,$A12,Buchungen!$A$5:$A$1004,">="&DATE(Start!$C$6,I$3,1),Buchungen!$A$5:$A$1004,"<"&DATE(Start!$C$6,I$3+1,1))) -> 0 | J12: =IF($A12="",0,SUMIFS(Buchungen!$D$5:$D$1004,Buchungen!$B$5:$B$1004,$A12,Buchungen!$A$5:$A$1004,">="&DATE(Start!$C$6,J$3,1),Buchungen!$A$5:$A$1004,"<"&DATE(Start!$C$6,J$3+1,1))) -> 0 | ... N12: =IF($A12="",0,SUMIFS(Buchungen!$D$5:$D$1004,Buchungen!$B$5:$B$1004,$A12,Buchungen!$A$5:$A$1004,">="&DATE(Start!$C$6,N$3,1),Buchungen!$A$5:$A$1004,"<"&DATE(Start!$C$6,N$3+1,1))) -> 0 | O12: =SUM(C12:N12) -> 0 | P12: =IF($A12="","",O12/MAX(1,$B$48)) | Q12: =IF(OR($A12="",$B12=0),"",B12*$B$48) | R12: =IF(OR($A12="",$B12=0),"",O12-Q12)
A13: =IF(Kategorien!A12="","",Kategorien!A12) | B13: =IF($A13="",0,N(Kategorien!C12)) -> 0 | C13: =IF($A13="",0,SUMIFS(Buchungen!$D$5:$D$1004,Buchungen!$B$5:$B$1004,$A13,Buchungen!$A$5:$A$1004,">="&DATE(Start!$C$6,C$3,1),Buchungen!$A$5:$A$1004,"<"&DATE(Start!$C$6,C$3+1,1))) -> 0 | D13: =IF($A13="",0,SUMIFS(Buchungen!$D$5:$D$1004,Buchungen!$B$5:$B$1004,$A13,Buchungen!$A$5:$A$1004,">="&DATE(Start!$C$6,D$3,1),Buchungen!$A$5:$A$1004,"<"&DATE(Start!$C$6,D$3+1,1))) -> 0 | E13: =IF($A13="",0,SUMIFS(Buchungen!$D$5:$D$1004,Buchungen!$B$5:$B$1004,$A13,Buchungen!$A$5:$A$1004,">="&DATE(Start!$C$6,E$3,1),Buchungen!$A$5:$A$1004,"<"&DATE(Start!$C$6,E$3+1,1))) -> 0 | F13: =IF($A13="",0,SUMIFS(Buchungen!$D$5:$D$1004,Buchungen!$B$5:$B$1004,$A13,Buchungen!$A$5:$A$1004,">="&DATE(Start!$C$6,F$3,1),Buchungen!$A$5:$A$1004,"<"&DATE(Start!$C$6,F$3+1,1))) -> 0 | G13: =IF($A13="",0,SUMIFS(Buchungen!$D$5:$D$1004,Buchungen!$B$5:$B$1004,$A13,Buchungen!$A$5:$A$1004,">="&DATE(Start!$C$6,G$3,1),Buchungen!$A$5:$A$1004,"<"&DATE(Start!$C$6,G$3+1,1))) -> 0 | H13: =IF($A13="",0,SUMIFS(Buchungen!$D$5:$D$1004,Buchungen!$B$5:$B$1004,$A13,Buchungen!$A$5:$A$1004,">="&DATE(Start!$C$6,H$3,1),Buchungen!$A$5:$A$1004,"<"&DATE(Start!$C$6,H$3+1,1))) -> 0 | I13: =IF($A13="",0,SUMIFS(Buchungen!$D$5:$D$1004,Buchungen!$B$5:$B$1004,$A13,Buchungen!$A$5:$A$1004,">="&DATE(Start!$C$6,I$3,1),Buchungen!$A$5:$A$1004,"<"&DATE(Start!$C$6,I$3+1,1))) -> 0 | J13: =IF($A13="",0,SUMIFS(Buchungen!$D$5:$D$1004,Buchungen!$B$5:$B$1004,$A13,Buchungen!$A$5:$A$1004,">="&DATE(Start!$C$6,J$3,1),Buchungen!$A$5:$A$1004,"<"&DATE(Start!$C$6,J$3+1,1))) -> 0 | ... N13: =IF($A13="",0,SUMIFS(Buchungen!$D$5:$D$1004,Buchungen!$B$5:$B$1004,$A13,Buchungen!$A$5:$A$1004,">="&DATE(Start!$C$6,N$3,1),Buchungen!$A$5:$A$1004,"<"&DATE(Start!$C$6,N$3+1,1))) -> 0 | O13: =SUM(C13:N13) -> 0 | P13: =IF($A13="","",O13/MAX(1,$B$48)) | Q13: =IF(OR($A13="",$B13=0),"",B13*$B$48) | R13: =IF(OR($A13="",$B13=0),"",O13-Q13)
A14: Summe Einnahmen | B14: =SUM(B6:B13) -> 0 | C14: =SUM(C6:C13) -> 2100 | D14: =SUM(D6:D13) -> 0 | E14: =SUM(E6:E13) -> 0 | F14: =SUM(F6:F13) -> 0 | G14: =SUM(G6:G13) -> 0 | H14: =SUM(H6:H13) -> 0 | I14: =SUM(I6:I13) -> 0 | ... O14: =SUM(O6:O13) -> 2100 | P14: =O14/MAX(1,$B$48) -> 2100 | Q14: =SUM(Q6:Q13) -> 0
A16: AUSGABEN
A17: =IF(Kategorien!A13="","",Kategorien!A13) -> Miete & Nebenkosten | B17: =IF($A17="",0,N(Kategorien!C13)) -> 0 | C17: =IF($A17="",0,SUMIFS(Buchungen!$D$5:$D$1004,Buchungen!$B$5:$B$1004,$A17,Buchungen!$A$5:$A$1004,">="&DATE(Start!$C$6,C$3,1),Buchungen!$A$5:$A$1004,"<"&DATE(Start!$C$6,C$3+1,1))) -> 0 | D17: =IF($A17="",0,SUMIFS(Buchungen!$D$5:$D$1004,Buchungen!$B$5:$B$1004,$A17,Buchungen!$A$5:$A$1004,">="&DATE(Start!$C$6,D$3,1),Buchungen!$A$5:$A$1004,"<"&DATE(Start!$C$6,D$3+1,1))) -> 0 | E17: =IF($A17="",0,SUMIFS(Buchungen!$D$5:$D$1004,Buchungen!$B$5:$B$1004,$A17,Buchungen!$A$5:$A$1004,">="&DATE(Start!$C$6,E$3,1),Buchungen!$A$5:$A$1004,"<"&DATE(Start!$C$6,E$3+1,1))) -> 0 | F17: =IF($A17="",0,SUMIFS(Buchungen!$D$5:$D$1004,Buchungen!$B$5:$B$1004,$A17,Buchungen!$A$5:$A$1004,">="&DATE(Start!$C$6,F$3,1),Buchungen!$A$5:$A$1004,"<"&DATE(Start!$C$6,F$3+1,1))) -> 0 | G17: =IF($A17="",0,SUMIFS(Buchungen!$D$5:$D$1004,Buchungen!$B$5:$B$1004,$A17,Buchungen!$A$5:$A$1004,">="&DATE(Start!$C$6,G$3,1),Buchungen!$A$5:$A$1004,"<"&DATE(Start!$C$6,G$3+1,1))) -> 0 | H17: =IF($A17="",0,SUMIFS(Buchungen!$D$5:$D$1004,Buchungen!$B$5:$B$1004,$A17,Buchungen!$A$5:$A$1004,">="&DATE(Start!$C$6,H$3,1),Buchungen!$A$5:$A$1004,"<"&DATE(Start!$C$6,H$3+1,1))) -> 0 | I17: =IF($A17="",0,SUMIFS(Buchungen!$D$5:$D$1004,Buchungen!$B$5:$B$1004,$A17,Buchungen!$A$5:$A$1004,">="&DATE(Start!$C$6,I$3,1),Buchungen!$A$5:$A$1004,"<"&DATE(Start!$C$6,I$3+1,1))) -> 0 | J17: =IF($A17="",0,SUMIFS(Buchungen!$D$5:$D$1004,Buchungen!$B$5:$B$1004,$A17,Buchungen!$A$5:$A$1004,">="&DATE(Start!$C$6,J$3,1),Buchungen!$A$5:$A$1004,"<"&DATE(Start!$C$6,J$3+1,1))) -> 0 | ... N17: =IF($A17="",0,SUMIFS(Buchungen!$D$5:$D$1004,Buchungen!$B$5:$B$1004,$A17,Buchungen!$A$5:$A$1004,">="&DATE(Start!$C$6,N$3,1),Buchungen!$A$5:$A$1004,"<"&DATE(Start!$C$6,N$3+1,1))) -> 0 | O17: =SUM(C17:N17) -> 0 | P17: =IF($A17="","",O17/MAX(1,$B$48)) -> 0 | Q17: =IF(OR($A17="",$B17=0),"",B17*$B$48) | R17: =IF(OR($A17="",$B17=0),"",Q17-O17) | S17: =IF($A17="",-1,O17+(100-ROW())/1000000) -> 8.3e-05
A18: =IF(Kategorien!A14="","",Kategorien!A14) -> Strom & Internet | B18: =IF($A18="",0,N(Kategorien!C14)) -> 0 | C18: =IF($A18="",0,SUMIFS(Buchungen!$D$5:$D$1004,Buchungen!$B$5:$B$1004,$A18,Buchungen!$A$5:$A$1004,">="&DATE(Start!$C$6,C$3,1),Buchungen!$A$5:$A$1004,"<"&DATE(Start!$C$6,C$3+1,1))) -> 0 | D18: =IF($A18="",0,SUMIFS(Buchungen!$D$5:$D$1004,Buchungen!$B$5:$B$1004,$A18,Buchungen!$A$5:$A$1004,">="&DATE(Start!$C$6,D$3,1),Buchungen!$A$5:$A$1004,"<"&DATE(Start!$C$6,D$3+1,1))) -> 0 | E18: =IF($A18="",0,SUMIFS(Buchungen!$D$5:$D$1004,Buchungen!$B$5:$B$1004,$A18,Buchungen!$A$5:$A$1004,">="&DATE(Start!$C$6,E$3,1),Buchungen!$A$5:$A$1004,"<"&DATE(Start!$C$6,E$3+1,1))) -> 0 | F18: =IF($A18="",0,SUMIFS(Buchungen!$D$5:$D$1004,Buchungen!$B$5:$B$1004,$A18,Buchungen!$A$5:$A$1004,">="&DATE(Start!$C$6,F$3,1),Buchungen!$A$5:$A$1004,"<"&DATE(Start!$C$6,F$3+1,1))) -> 0 | G18: =IF($A18="",0,SUMIFS(Buchungen!$D$5:$D$1004,Buchungen!$B$5:$B$1004,$A18,Buchungen!$A$5:$A$1004,">="&DATE(Start!$C$6,G$3,1),Buchungen!$A$5:$A$1004,"<"&DATE(Start!$C$6,G$3+1,1))) -> 0 | H18: =IF($A18="",0,SUMIFS(Buchungen!$D$5:$D$1004,Buchungen!$B$5:$B$1004,$A18,Buchungen!$A$5:$A$1004,">="&DATE(Start!$C$6,H$3,1),Buchungen!$A$5:$A$1004,"<"&DATE(Start!$C$6,H$3+1,1))) -> 0 | I18: =IF($A18="",0,SUMIFS(Buchungen!$D$5:$D$1004,Buchungen!$B$5:$B$1004,$A18,Buchungen!$A$5:$A$1004,">="&DATE(Start!$C$6,I$3,1),Buchungen!$A$5:$A$1004,"<"&DATE(Start!$C$6,I$3+1,1))) -> 0 | J18: =IF($A18="",0,SUMIFS(Buchungen!$D$5:$D$1004,Buchungen!$B$5:$B$1004,$A18,Buchungen!$A$5:$A$1004,">="&DATE(Start!$C$6,J$3,1),Buchungen!$A$5:$A$1004,"<"&DATE(Start!$C$6,J$3+1,1))) -> 0 | ... N18: =IF($A18="",0,SUMIFS(Buchungen!$D$5:$D$1004,Buchungen!$B$5:$B$1004,$A18,Buchungen!$A$5:$A$1004,">="&DATE(Start!$C$6,N$3,1),Buchungen!$A$5:$A$1004,"<"&DATE(Start!$C$6,N$3+1,1))) -> 0 | O18: =SUM(C18:N18) -> 0 | P18: =IF($A18="","",O18/MAX(1,$B$48)) -> 0 | Q18: =IF(OR($A18="",$B18=0),"",B18*$B$48) | R18: =IF(OR($A18="",$B18=0),"",Q18-O18) | S18: =IF($A18="",-1,O18+(100-ROW())/1000000) -> 8.2e-05
A19: =IF(Kategorien!A15="","",Kategorien!A15) -> Lebensmittel | B19: =IF($A19="",0,N(Kategorien!C15)) -> 0 | C19: =IF($A19="",0,SUMIFS(Buchungen!$D$5:$D$1004,Buchungen!$B$5:$B$1004,$A19,Buchungen!$A$5:$A$1004,">="&DATE(Start!$C$6,C$3,1),Buchungen!$A$5:$A$1004,"<"&DATE(Start!$C$6,C$3+1,1))) -> 0 | D19: =IF($A19="",0,SUMIFS(Buchungen!$D$5:$D$1004,Buchungen!$B$5:$B$1004,$A19,Buchungen!$A$5:$A$1004,">="&DATE(Start!$C$6,D$3,1),Buchungen!$A$5:$A$1004,"<"&DATE(Start!$C$6,D$3+1,1))) -> 0 | E19: =IF($A19="",0,SUMIFS(Buchungen!$D$5:$D$1004,Buchungen!$B$5:$B$1004,$A19,Buchungen!$A$5:$A$1004,">="&DATE(Start!$C$6,E$3,1),Buchungen!$A$5:$A$1004,"<"&DATE(Start!$C$6,E$3+1,1))) -> 0 | F19: =IF($A19="",0,SUMIFS(Buchungen!$D$5:$D$1004,Buchungen!$B$5:$B$1004,$A19,Buchungen!$A$5:$A$1004,">="&DATE(Start!$C$6,F$3,1),Buchungen!$A$5:$A$1004,"<"&DATE(Start!$C$6,F$3+1,1))) -> 0 | G19: =IF($A19="",0,SUMIFS(Buchungen!$D$5:$D$1004,Buchungen!$B$5:$B$1004,$A19,Buchungen!$A$5:$A$1004,">="&DATE(Start!$C$6,G$3,1),Buchungen!$A$5:$A$1004,"<"&DATE(Start!$C$6,G$3+1,1))) -> 0 | H19: =IF($A19="",0,SUMIFS(Buchungen!$D$5:$D$1004,Buchungen!$B$5:$B$1004,$A19,Buchungen!$A$5:$A$1004,">="&DATE(Start!$C$6,H$3,1),Buchungen!$A$5:$A$1004,"<"&DATE(Start!$C$6,H$3+1,1))) -> 0 | I19: =IF($A19="",0,SUMIFS(Buchungen!$D$5:$D$1004,Buchungen!$B$5:$B$1004,$A19,Buchungen!$A$5:$A$1004,">="&DATE(Start!$C$6,I$3,1),Buchungen!$A$5:$A$1004,"<"&DATE(Start!$C$6,I$3+1,1))) -> 0 | J19: =IF($A19="",0,SUMIFS(Buchungen!$D$5:$D$1004,Buchungen!$B$5:$B$1004,$A19,Buchungen!$A$5:$A$1004,">="&DATE(Start!$C$6,J$3,1),Buchungen!$A$5:$A$1004,"<"&DATE(Start!$C$6,J$3+1,1))) -> 0 | ... N19: =IF($A19="",0,SUMIFS(Buchungen!$D$5:$D$1004,Buchungen!$B$5:$B$1004,$A19,Buchungen!$A$5:$A$1004,">="&DATE(Start!$C$6,N$3,1),Buchungen!$A$5:$A$1004,"<"&DATE(Start!$C$6,N$3+1,1))) -> 0 | O19: =SUM(C19:N19) -> 0 | P19: =IF($A19="","",O19/MAX(1,$B$48)) -> 0 | Q19: =IF(OR($A19="",$B19=0),"",B19*$B$48) | R19: =IF(OR($A19="",$B19=0),"",Q19-O19) | S19: =IF($A19="",-1,O19+(100-ROW())/1000000) -> 8.1e-05
A20: =IF(Kategorien!A16="","",Kategorien!A16) -> Handy & Abos | B20: =IF($A20="",0,N(Kategorien!C16)) -> 0 | C20: =IF($A20="",0,SUMIFS(Buchungen!$D$5:$D$1004,Buchungen!$B$5:$B$1004,$A20,Buchungen!$A$5:$A$1004,">="&DATE(Start!$C$6,C$3,1),Buchungen!$A$5:$A$1004,"<"&DATE(Start!$C$6,C$3+1,1))) -> 0 | D20: =IF($A20="",0,SUMIFS(Buchungen!$D$5:$D$1004,Buchungen!$B$5:$B$1004,$A20,Buchungen!$A$5:$A$1004,">="&DATE(Start!$C$6,D$3,1),Buchungen!$A$5:$A$1004,"<"&DATE(Start!$C$6,D$3+1,1))) -> 0 | E20: =IF($A20="",0,SUMIFS(Buchungen!$D$5:$D$1004,Buchungen!$B$5:$B$1004,$A20,Buchungen!$A$5:$A$1004,">="&DATE(Start!$C$6,E$3,1),Buchungen!$A$5:$A$1004,"<"&DATE(Start!$C$6,E$3+1,1))) -> 0 | F20: =IF($A20="",0,SUMIFS(Buchungen!$D$5:$D$1004,Buchungen!$B$5:$B$1004,$A20,Buchungen!$A$5:$A$1004,">="&DATE(Start!$C$6,F$3,1),Buchungen!$A$5:$A$1004,"<"&DATE(Start!$C$6,F$3+1,1))) -> 0 | G20: =IF($A20="",0,SUMIFS(Buchungen!$D$5:$D$1004,Buchungen!$B$5:$B$1004,$A20,Buchungen!$A$5:$A$1004,">="&DATE(Start!$C$6,G$3,1),Buchungen!$A$5:$A$1004,"<"&DATE(Start!$C$6,G$3+1,1))) -> 0 | H20: =IF($A20="",0,SUMIFS(Buchungen!$D$5:$D$1004,Buchungen!$B$5:$B$1004,$A20,Buchungen!$A$5:$A$1004,">="&DATE(Start!$C$6,H$3,1),Buchungen!$A$5:$A$1004,"<"&DATE(Start!$C$6,H$3+1,1))) -> 0 | I20: =IF($A20="",0,SUMIFS(Buchungen!$D$5:$D$1004,Buchungen!$B$5:$B$1004,$A20,Buchungen!$A$5:$A$1004,">="&DATE(Start!$C$6,I$3,1),Buchungen!$A$5:$A$1004,"<"&DATE(Start!$C$6,I$3+1,1))) -> 0 | J20: =IF($A20="",0,SUMIFS(Buchungen!$D$5:$D$1004,Buchungen!$B$5:$B$1004,$A20,Buchungen!$A$5:$A$1004,">="&DATE(Start!$C$6,J$3,1),Buchungen!$A$5:$A$1004,"<"&DATE(Start!$C$6,J$3+1,1))) -> 0 | ... N20: =IF($A20="",0,SUMIFS(Buchungen!$D$5:$D$1004,Buchungen!$B$5:$B$1004,$A20,Buchungen!$A$5:$A$1004,">="&DATE(Start!$C$6,N$3,1),Buchungen!$A$5:$A$1004,"<"&DATE(Start!$C$6,N$3+1,1))) -> 0 | O20: =SUM(C20:N20) -> 0 | P20: =IF($A20="","",O20/MAX(1,$B$48)) -> 0 | Q20: =IF(OR($A20="",$B20=0),"",B20*$B$48) | R20: =IF(OR($A20="",$B20=0),"",Q20-O20) | S20: =IF($A20="",-1,O20+(100-ROW())/1000000) -> 8e-05
A21: =IF(Kategorien!A17="","",Kategorien!A17) -> Mobilität (Auto/ÖPNV) | B21: =IF($A21="",0,N(Kategorien!C17)) -> 0 | C21: =IF($A21="",0,SUMIFS(Buchungen!$D$5:$D$1004,Buchungen!$B$5:$B$1004,$A21,Buchungen!$A$5:$A$1004,">="&DATE(Start!$C$6,C$3,1),Buchungen!$A$5:$A$1004,"<"&DATE(Start!$C$6,C$3+1,1))) -> 0 | D21: =IF($A21="",0,SUMIFS(Buchungen!$D$5:$D$1004,Buchungen!$B$5:$B$1004,$A21,Buchungen!$A$5:$A$1004,">="&DATE(Start!$C$6,D$3,1),Buchungen!$A$5:$A$1004,"<"&DATE(Start!$C$6,D$3+1,1))) -> 0 | E21: =IF($A21="",0,SUMIFS(Buchungen!$D$5:$D$1004,Buchungen!$B$5:$B$1004,$A21,Buchungen!$A$5:$A$1004,">="&DATE(Start!$C$6,E$3,1),Buchungen!$A$5:$A$1004,"<"&DATE(Start!$C$6,E$3+1,1))) -> 0 | F21: =IF($A21="",0,SUMIFS(Buchungen!$D$5:$D$1004,Buchungen!$B$5:$B$1004,$A21,Buchungen!$A$5:$A$1004,">="&DATE(Start!$C$6,F$3,1),Buchungen!$A$5:$A$1004,"<"&DATE(Start!$C$6,F$3+1,1))) -> 0 | G21: =IF($A21="",0,SUMIFS(Buchungen!$D$5:$D$1004,Buchungen!$B$5:$B$1004,$A21,Buchungen!$A$5:$A$1004,">="&DATE(Start!$C$6,G$3,1),Buchungen!$A$5:$A$1004,"<"&DATE(Start!$C$6,G$3+1,1))) -> 0 | H21: =IF($A21="",0,SUMIFS(Buchungen!$D$5:$D$1004,Buchungen!$B$5:$B$1004,$A21,Buchungen!$A$5:$A$1004,">="&DATE(Start!$C$6,H$3,1),Buchungen!$A$5:$A$1004,"<"&DATE(Start!$C$6,H$3+1,1))) -> 0 | I21: =IF($A21="",0,SUMIFS(Buchungen!$D$5:$D$1004,Buchungen!$B$5:$B$1004,$A21,Buchungen!$A$5:$A$1004,">="&DATE(Start!$C$6,I$3,1),Buchungen!$A$5:$A$1004,"<"&DATE(Start!$C$6,I$3+1,1))) -> 0 | J21: =IF($A21="",0,SUMIFS(Buchungen!$D$5:$D$1004,Buchungen!$B$5:$B$1004,$A21,Buchungen!$A$5:$A$1004,">="&DATE(Start!$C$6,J$3,1),Buchungen!$A$5:$A$1004,"<"&DATE(Start!$C$6,J$3+1,1))) -> 0 | ... N21: =IF($A21="",0,SUMIFS(Buchungen!$D$5:$D$1004,Buchungen!$B$5:$B$1004,$A21,Buchungen!$A$5:$A$1004,">="&DATE(Start!$C$6,N$3,1),Buchungen!$A$5:$A$1004,"<"&DATE(Start!$C$6,N$3+1,1))) -> 0 | O21: =SUM(C21:N21) -> 0 | P21: =IF($A21="","",O21/MAX(1,$B$48)) -> 0 | Q21: =IF(OR($A21="",$B21=0),"",B21*$B$48) | R21: =IF(OR($A21="",$B21=0),"",Q21-O21) | S21: =IF($A21="",-1,O21+(100-ROW())/1000000) -> 7.9e-05
A22: =IF(Kategorien!A18="","",Kategorien!A18) -> Versicherungen | B22: =IF($A22="",0,N(Kategorien!C18)) -> 0 | C22: =IF($A22="",0,SUMIFS(Buchungen!$D$5:$D$1004,Buchungen!$B$5:$B$1004,$A22,Buchungen!$A$5:$A$1004,">="&DATE(Start!$C$6,C$3,1),Buchungen!$A$5:$A$1004,"<"&DATE(Start!$C$6,C$3+1,1))) -> 0 | D22: =IF($A22="",0,SUMIFS(Buchungen!$D$5:$D$1004,Buchungen!$B$5:$B$1004,$A22,Buchungen!$A$5:$A$1004,">="&DATE(Start!$C$6,D$3,1),Buchungen!$A$5:$A$1004,"<"&DATE(Start!$C$6,D$3+1,1))) -> 0 | E22: =IF($A22="",0,SUMIFS(Buchungen!$D$5:$D$1004,Buchungen!$B$5:$B$1004,$A22,Buchungen!$A$5:$A$1004,">="&DATE(Start!$C$6,E$3,1),Buchungen!$A$5:$A$1004,"<"&DATE(Start!$C$6,E$3+1,1))) -> 0 | F22: =IF($A22="",0,SUMIFS(Buchungen!$D$5:$D$1004,Buchungen!$B$5:$B$1004,$A22,Buchungen!$A$5:$A$1004,">="&DATE(Start!$C$6,F$3,1),Buchungen!$A$5:$A$1004,"<"&DATE(Start!$C$6,F$3+1,1))) -> 0 | G22: =IF($A22="",0,SUMIFS(Buchungen!$D$5:$D$1004,Buchungen!$B$5:$B$1004,$A22,Buchungen!$A$5:$A$1004,">="&DATE(Start!$C$6,G$3,1),Buchungen!$A$5:$A$1004,"<"&DATE(Start!$C$6,G$3+1,1))) -> 0 | H22: =IF($A22="",0,SUMIFS(Buchungen!$D$5:$D$1004,Buchungen!$B$5:$B$1004,$A22,Buchungen!$A$5:$A$1004,">="&DATE(Start!$C$6,H$3,1),Buchungen!$A$5:$A$1004,"<"&DATE(Start!$C$6,H$3+1,1))) -> 0 | I22: =IF($A22="",0,SUMIFS(Buchungen!$D$5:$D$1004,Buchungen!$B$5:$B$1004,$A22,Buchungen!$A$5:$A$1004,">="&DATE(Start!$C$6,I$3,1),Buchungen!$A$5:$A$1004,"<"&DATE(Start!$C$6,I$3+1,1))) -> 0 | J22: =IF($A22="",0,SUMIFS(Buchungen!$D$5:$D$1004,Buchungen!$B$5:$B$1004,$A22,Buchungen!$A$5:$A$1004,">="&DATE(Start!$C$6,J$3,1),Buchungen!$A$5:$A$1004,"<"&DATE(Start!$C$6,J$3+1,1))) -> 0 | ... N22: =IF($A22="",0,SUMIFS(Buchungen!$D$5:$D$1004,Buchungen!$B$5:$B$1004,$A22,Buchungen!$A$5:$A$1004,">="&DATE(Start!$C$6,N$3,1),Buchungen!$A$5:$A$1004,"<"&DATE(Start!$C$6,N$3+1,1))) -> 0 | O22: =SUM(C22:N22) -> 0 | P22: =IF($A22="","",O22/MAX(1,$B$48)) -> 0 | Q22: =IF(OR($A22="",$B22=0),"",B22*$B$48) | R22: =IF(OR($A22="",$B22=0),"",Q22-O22) | S22: =IF($A22="",-1,O22+(100-ROW())/1000000) -> 7.8e-05
A23: =IF(Kategorien!A19="","",Kategorien!A19) -> Freizeit & Ausgehen | B23: =IF($A23="",0,N(Kategorien!C19)) -> 0 | C23: =IF($A23="",0,SUMIFS(Buchungen!$D$5:$D$1004,Buchungen!$B$5:$B$1004,$A23,Buchungen!$A$5:$A$1004,">="&DATE(Start!$C$6,C$3,1),Buchungen!$A$5:$A$1004,"<"&DATE(Start!$C$6,C$3+1,1))) -> 0 | D23: =IF($A23="",0,SUMIFS(Buchungen!$D$5:$D$1004,Buchungen!$B$5:$B$1004,$A23,Buchungen!$A$5:$A$1004,">="&DATE(Start!$C$6,D$3,1),Buchungen!$A$5:$A$1004,"<"&DATE(Start!$C$6,D$3+1,1))) -> 0 | E23: =IF($A23="",0,SUMIFS(Buchungen!$D$5:$D$1004,Buchungen!$B$5:$B$1004,$A23,Buchungen!$A$5:$A$1004,">="&DATE(Start!$C$6,E$3,1),Buchungen!$A$5:$A$1004,"<"&DATE(Start!$C$6,E$3+1,1))) -> 0 | F23: =IF($A23="",0,SUMIFS(Buchungen!$D$5:$D$1004,Buchungen!$B$5:$B$1004,$A23,Buchungen!$A$5:$A$1004,">="&DATE(Start!$C$6,F$3,1),Buchungen!$A$5:$A$1004,"<"&DATE(Start!$C$6,F$3+1,1))) -> 0 | G23: =IF($A23="",0,SUMIFS(Buchungen!$D$5:$D$1004,Buchungen!$B$5:$B$1004,$A23,Buchungen!$A$5:$A$1004,">="&DATE(Start!$C$6,G$3,1),Buchungen!$A$5:$A$1004,"<"&DATE(Start!$C$6,G$3+1,1))) -> 0 | H23: =IF($A23="",0,SUMIFS(Buchungen!$D$5:$D$1004,Buchungen!$B$5:$B$1004,$A23,Buchungen!$A$5:$A$1004,">="&DATE(Start!$C$6,H$3,1),Buchungen!$A$5:$A$1004,"<"&DATE(Start!$C$6,H$3+1,1))) -> 0 | I23: =IF($A23="",0,SUMIFS(Buchungen!$D$5:$D$1004,Buchungen!$B$5:$B$1004,$A23,Buchungen!$A$5:$A$1004,">="&DATE(Start!$C$6,I$3,1),Buchungen!$A$5:$A$1004,"<"&DATE(Start!$C$6,I$3+1,1))) -> 0 | J23: =IF($A23="",0,SUMIFS(Buchungen!$D$5:$D$1004,Buchungen!$B$5:$B$1004,$A23,Buchungen!$A$5:$A$1004,">="&DATE(Start!$C$6,J$3,1),Buchungen!$A$5:$A$1004,"<"&DATE(Start!$C$6,J$3+1,1))) -> 0 | ... N23: =IF($A23="",0,SUMIFS(Buchungen!$D$5:$D$1004,Buchungen!$B$5:$B$1004,$A23,Buchungen!$A$5:$A$1004,">="&DATE(Start!$C$6,N$3,1),Buchungen!$A$5:$A$1004,"<"&DATE(Start!$C$6,N$3+1,1))) -> 0 | O23: =SUM(C23:N23) -> 0 | P23: =IF($A23="","",O23/MAX(1,$B$48)) -> 0 | Q23: =IF(OR($A23="",$B23=0),"",B23*$B$48) | R23: =IF(OR($A23="",$B23=0),"",Q23-O23) | S23: =IF($A23="",-1,O23+(100-ROW())/1000000) -> 7.7e-05
A24: =IF(Kategorien!A20="","",Kategorien!A20) -> Kleidung | B24: =IF($A24="",0,N(Kategorien!C20)) -> 0 | C24: =IF($A24="",0,SUMIFS(Buchungen!$D$5:$D$1004,Buchungen!$B$5:$B$1004,$A24,Buchungen!$A$5:$A$1004,">="&DATE(Start!$C$6,C$3,1),Buchungen!$A$5:$A$1004,"<"&DATE(Start!$C$6,C$3+1,1))) -> 0 | D24: =IF($A24="",0,SUMIFS(Buchungen!$D$5:$D$1004,Buchungen!$B$5:$B$1004,$A24,Buchungen!$A$5:$A$1004,">="&DATE(Start!$C$6,D$3,1),Buchungen!$A$5:$A$1004,"<"&DATE(Start!$C$6,D$3+1,1))) -> 0 | E24: =IF($A24="",0,SUMIFS(Buchungen!$D$5:$D$1004,Buchungen!$B$5:$B$1004,$A24,Buchungen!$A$5:$A$1004,">="&DATE(Start!$C$6,E$3,1),Buchungen!$A$5:$A$1004,"<"&DATE(Start!$C$6,E$3+1,1))) -> 0 | F24: =IF($A24="",0,SUMIFS(Buchungen!$D$5:$D$1004,Buchungen!$B$5:$B$1004,$A24,Buchungen!$A$5:$A$1004,">="&DATE(Start!$C$6,F$3,1),Buchungen!$A$5:$A$1004,"<"&DATE(Start!$C$6,F$3+1,1))) -> 0 | G24: =IF($A24="",0,SUMIFS(Buchungen!$D$5:$D$1004,Buchungen!$B$5:$B$1004,$A24,Buchungen!$A$5:$A$1004,">="&DATE(Start!$C$6,G$3,1),Buchungen!$A$5:$A$1004,"<"&DATE(Start!$C$6,G$3+1,1))) -> 0 | H24: =IF($A24="",0,SUMIFS(Buchungen!$D$5:$D$1004,Buchungen!$B$5:$B$1004,$A24,Buchungen!$A$5:$A$1004,">="&DATE(Start!$C$6,H$3,1),Buchungen!$A$5:$A$1004,"<"&DATE(Start!$C$6,H$3+1,1))) -> 0 | I24: =IF($A24="",0,SUMIFS(Buchungen!$D$5:$D$1004,Buchungen!$B$5:$B$1004,$A24,Buchungen!$A$5:$A$1004,">="&DATE(Start!$C$6,I$3,1),Buchungen!$A$5:$A$1004,"<"&DATE(Start!$C$6,I$3+1,1))) -> 0 | J24: =IF($A24="",0,SUMIFS(Buchungen!$D$5:$D$1004,Buchungen!$B$5:$B$1004,$A24,Buchungen!$A$5:$A$1004,">="&DATE(Start!$C$6,J$3,1),Buchungen!$A$5:$A$1004,"<"&DATE(Start!$C$6,J$3+1,1))) -> 0 | ... N24: =IF($A24="",0,SUMIFS(Buchungen!$D$5:$D$1004,Buchungen!$B$5:$B$1004,$A24,Buchungen!$A$5:$A$1004,">="&DATE(Start!$C$6,N$3,1),Buchungen!$A$5:$A$1004,"<"&DATE(Start!$C$6,N$3+1,1))) -> 0 | O24: =SUM(C24:N24) -> 0 | P24: =IF($A24="","",O24/MAX(1,$B$48)) -> 0 | Q24: =IF(OR($A24="",$B24=0),"",B24*$B$48) | R24: =IF(OR($A24="",$B24=0),"",Q24-O24) | S24: =IF($A24="",-1,O24+(100-ROW())/1000000) -> 7.6e-05
A25: =IF(Kategorien!A21="","",Kategorien!A21) -> Gesundheit & Drogerie | B25: =IF($A25="",0,N(Kategorien!C21)) -> 0 | C25: =IF($A25="",0,SUMIFS(Buchungen!$D$5:$D$1004,Buchungen!$B$5:$B$1004,$A25,Buchungen!$A$5:$A$1004,">="&DATE(Start!$C$6,C$3,1),Buchungen!$A$5:$A$1004,"<"&DATE(Start!$C$6,C$3+1,1))) -> 0 | D25: =IF($A25="",0,SUMIFS(Buchungen!$D$5:$D$1004,Buchungen!$B$5:$B$1004,$A25,Buchungen!$A$5:$A$1004,">="&DATE(Start!$C$6,D$3,1),Buchungen!$A$5:$A$1004,"<"&DATE(Start!$C$6,D$3+1,1))) -> 0 | E25: =IF($A25="",0,SUMIFS(Buchungen!$D$5:$D$1004,Buchungen!$B$5:$B$1004,$A25,Buchungen!$A$5:$A$1004,">="&DATE(Start!$C$6,E$3,1),Buchungen!$A$5:$A$1004,"<"&DATE(Start!$C$6,E$3+1,1))) -> 0 | F25: =IF($A25="",0,SUMIFS(Buchungen!$D$5:$D$1004,Buchungen!$B$5:$B$1004,$A25,Buchungen!$A$5:$A$1004,">="&DATE(Start!$C$6,F$3,1),Buchungen!$A$5:$A$1004,"<"&DATE(Start!$C$6,F$3+1,1))) -> 0 | G25: =IF($A25="",0,SUMIFS(Buchungen!$D$5:$D$1004,Buchungen!$B$5:$B$1004,$A25,Buchungen!$A$5:$A$1004,">="&DATE(Start!$C$6,G$3,1),Buchungen!$A$5:$A$1004,"<"&DATE(Start!$C$6,G$3+1,1))) -> 0 | H25: =IF($A25="",0,SUMIFS(Buchungen!$D$5:$D$1004,Buchungen!$B$5:$B$1004,$A25,Buchungen!$A$5:$A$1004,">="&DATE(Start!$C$6,H$3,1),Buchungen!$A$5:$A$1004,"<"&DATE(Start!$C$6,H$3+1,1))) -> 0 | I25: =IF($A25="",0,SUMIFS(Buchungen!$D$5:$D$1004,Buchungen!$B$5:$B$1004,$A25,Buchungen!$A$5:$A$1004,">="&DATE(Start!$C$6,I$3,1),Buchungen!$A$5:$A$1004,"<"&DATE(Start!$C$6,I$3+1,1))) -> 0 | J25: =IF($A25="",0,SUMIFS(Buchungen!$D$5:$D$1004,Buchungen!$B$5:$B$1004,$A25,Buchungen!$A$5:$A$1004,">="&DATE(Start!$C$6,J$3,1),Buchungen!$A$5:$A$1004,"<"&DATE(Start!$C$6,J$3+1,1))) -> 0 | ... N25: =IF($A25="",0,SUMIFS(Buchungen!$D$5:$D$1004,Buchungen!$B$5:$B$1004,$A25,Buchungen!$A$5:$A$1004,">="&DATE(Start!$C$6,N$3,1),Buchungen!$A$5:$A$1004,"<"&DATE(Start!$C$6,N$3+1,1))) -> 0 | O25: =SUM(C25:N25) -> 0 | P25: =IF($A25="","",O25/MAX(1,$B$48)) -> 0 | Q25: =IF(OR($A25="",$B25=0),"",B25*$B$48) | R25: =IF(OR($A25="",$B25=0),"",Q25-O25) | S25: =IF($A25="",-1,O25+(100-ROW())/1000000) -> 7.5e-05
A26: =IF(Kategorien!A22="","",Kategorien!A22) -> Geschenke | B26: =IF($A26="",0,N(Kategorien!C22)) -> 0 | C26: =IF($A26="",0,SUMIFS(Buchungen!$D$5:$D$1004,Buchungen!$B$5:$B$1004,$A26,Buchungen!$A$5:$A$1004,">="&DATE(Start!$C$6,C$3,1),Buchungen!$A$5:$A$1004,"<"&DATE(Start!$C$6,C$3+1,1))) -> 0 | D26: =IF($A26="",0,SUMIFS(Buchungen!$D$5:$D$1004,Buchungen!$B$5:$B$1004,$A26,Buchungen!$A$5:$A$1004,">="&DATE(Start!$C$6,D$3,1),Buchungen!$A$5:$A$1004,"<"&DATE(Start!$C$6,D$3+1,1))) -> 0 | E26: =IF($A26="",0,SUMIFS(Buchungen!$D$5:$D$1004,Buchungen!$B$5:$B$1004,$A26,Buchungen!$A$5:$A$1004,">="&DATE(Start!$C$6,E$3,1),Buchungen!$A$5:$A$1004,"<"&DATE(Start!$C$6,E$3+1,1))) -> 0 | F26: =IF($A26="",0,SUMIFS(Buchungen!$D$5:$D$1004,Buchungen!$B$5:$B$1004,$A26,Buchungen!$A$5:$A$1004,">="&DATE(Start!$C$6,F$3,1),Buchungen!$A$5:$A$1004,"<"&DATE(Start!$C$6,F$3+1,1))) -> 0 | G26: =IF($A26="",0,SUMIFS(Buchungen!$D$5:$D$1004,Buchungen!$B$5:$B$1004,$A26,Buchungen!$A$5:$A$1004,">="&DATE(Start!$C$6,G$3,1),Buchungen!$A$5:$A$1004,"<"&DATE(Start!$C$6,G$3+1,1))) -> 0 | H26: =IF($A26="",0,SUMIFS(Buchungen!$D$5:$D$1004,Buchungen!$B$5:$B$1004,$A26,Buchungen!$A$5:$A$1004,">="&DATE(Start!$C$6,H$3,1),Buchungen!$A$5:$A$1004,"<"&DATE(Start!$C$6,H$3+1,1))) -> 0 | I26: =IF($A26="",0,SUMIFS(Buchungen!$D$5:$D$1004,Buchungen!$B$5:$B$1004,$A26,Buchungen!$A$5:$A$1004,">="&DATE(Start!$C$6,I$3,1),Buchungen!$A$5:$A$1004,"<"&DATE(Start!$C$6,I$3+1,1))) -> 0 | J26: =IF($A26="",0,SUMIFS(Buchungen!$D$5:$D$1004,Buchungen!$B$5:$B$1004,$A26,Buchungen!$A$5:$A$1004,">="&DATE(Start!$C$6,J$3,1),Buchungen!$A$5:$A$1004,"<"&DATE(Start!$C$6,J$3+1,1))) -> 0 | ... N26: =IF($A26="",0,SUMIFS(Buchungen!$D$5:$D$1004,Buchungen!$B$5:$B$1004,$A26,Buchungen!$A$5:$A$1004,">="&DATE(Start!$C$6,N$3,1),Buchungen!$A$5:$A$1004,"<"&DATE(Start!$C$6,N$3+1,1))) -> 0 | O26: =SUM(C26:N26) -> 0 | P26: =IF($A26="","",O26/MAX(1,$B$48)) -> 0 | Q26: =IF(OR($A26="",$B26=0),"",B26*$B$48) | R26: =IF(OR($A26="",$B26=0),"",Q26-O26) | S26: =IF($A26="",-1,O26+(100-ROW())/1000000) -> 7.4e-05
A27: =IF(Kategorien!A23="","",Kategorien!A23) -> Urlaub | B27: =IF($A27="",0,N(Kategorien!C23)) -> 0 | C27: =IF($A27="",0,SUMIFS(Buchungen!$D$5:$D$1004,Buchungen!$B$5:$B$1004,$A27,Buchungen!$A$5:$A$1004,">="&DATE(Start!$C$6,C$3,1),Buchungen!$A$5:$A$1004,"<"&DATE(Start!$C$6,C$3+1,1))) -> 0 | D27: =IF($A27="",0,SUMIFS(Buchungen!$D$5:$D$1004,Buchungen!$B$5:$B$1004,$A27,Buchungen!$A$5:$A$1004,">="&DATE(Start!$C$6,D$3,1),Buchungen!$A$5:$A$1004,"<"&DATE(Start!$C$6,D$3+1,1))) -> 0 | E27: =IF($A27="",0,SUMIFS(Buchungen!$D$5:$D$1004,Buchungen!$B$5:$B$1004,$A27,Buchungen!$A$5:$A$1004,">="&DATE(Start!$C$6,E$3,1),Buchungen!$A$5:$A$1004,"<"&DATE(Start!$C$6,E$3+1,1))) -> 0 | F27: =IF($A27="",0,SUMIFS(Buchungen!$D$5:$D$1004,Buchungen!$B$5:$B$1004,$A27,Buchungen!$A$5:$A$1004,">="&DATE(Start!$C$6,F$3,1),Buchungen!$A$5:$A$1004,"<"&DATE(Start!$C$6,F$3+1,1))) -> 0 | G27: =IF($A27="",0,SUMIFS(Buchungen!$D$5:$D$1004,Buchungen!$B$5:$B$1004,$A27,Buchungen!$A$5:$A$1004,">="&DATE(Start!$C$6,G$3,1),Buchungen!$A$5:$A$1004,"<"&DATE(Start!$C$6,G$3+1,1))) -> 0 | H27: =IF($A27="",0,SUMIFS(Buchungen!$D$5:$D$1004,Buchungen!$B$5:$B$1004,$A27,Buchungen!$A$5:$A$1004,">="&DATE(Start!$C$6,H$3,1),Buchungen!$A$5:$A$1004,"<"&DATE(Start!$C$6,H$3+1,1))) -> 0 | I27: =IF($A27="",0,SUMIFS(Buchungen!$D$5:$D$1004,Buchungen!$B$5:$B$1004,$A27,Buchungen!$A$5:$A$1004,">="&DATE(Start!$C$6,I$3,1),Buchungen!$A$5:$A$1004,"<"&DATE(Start!$C$6,I$3+1,1))) -> 0 | J27: =IF($A27="",0,SUMIFS(Buchungen!$D$5:$D$1004,Buchungen!$B$5:$B$1004,$A27,Buchungen!$A$5:$A$1004,">="&DATE(Start!$C$6,J$3,1),Buchungen!$A$5:$A$1004,"<"&DATE(Start!$C$6,J$3+1,1))) -> 0 | ... N27: =IF($A27="",0,SUMIFS(Buchungen!$D$5:$D$1004,Buchungen!$B$5:$B$1004,$A27,Buchungen!$A$5:$A$1004,">="&DATE(Start!$C$6,N$3,1),Buchungen!$A$5:$A$1004,"<"&DATE(Start!$C$6,N$3+1,1))) -> 0 | O27: =SUM(C27:N27) -> 0 | P27: =IF($A27="","",O27/MAX(1,$B$48)) -> 0 | Q27: =IF(OR($A27="",$B27=0),"",B27*$B$48) | R27: =IF(OR($A27="",$B27=0),"",Q27-O27) | S27: =IF($A27="",-1,O27+(100-ROW())/1000000) -> 7.3e-05
A28: =IF(Kategorien!A24="","",Kategorien!A24) -> Sonstiges | B28: =IF($A28="",0,N(Kategorien!C24)) -> 0 | C28: =IF($A28="",0,SUMIFS(Buchungen!$D$5:$D$1004,Buchungen!$B$5:$B$1004,$A28,Buchungen!$A$5:$A$1004,">="&DATE(Start!$C$6,C$3,1),Buchungen!$A$5:$A$1004,"<"&DATE(Start!$C$6,C$3+1,1))) -> 0 | D28: =IF($A28="",0,SUMIFS(Buchungen!$D$5:$D$1004,Buchungen!$B$5:$B$1004,$A28,Buchungen!$A$5:$A$1004,">="&DATE(Start!$C$6,D$3,1),Buchungen!$A$5:$A$1004,"<"&DATE(Start!$C$6,D$3+1,1))) -> 0 | E28: =IF($A28="",0,SUMIFS(Buchungen!$D$5:$D$1004,Buchungen!$B$5:$B$1004,$A28,Buchungen!$A$5:$A$1004,">="&DATE(Start!$C$6,E$3,1),Buchungen!$A$5:$A$1004,"<"&DATE(Start!$C$6,E$3+1,1))) -> 0 | F28: =IF($A28="",0,SUMIFS(Buchungen!$D$5:$D$1004,Buchungen!$B$5:$B$1004,$A28,Buchungen!$A$5:$A$1004,">="&DATE(Start!$C$6,F$3,1),Buchungen!$A$5:$A$1004,"<"&DATE(Start!$C$6,F$3+1,1))) -> 0 | G28: =IF($A28="",0,SUMIFS(Buchungen!$D$5:$D$1004,Buchungen!$B$5:$B$1004,$A28,Buchungen!$A$5:$A$1004,">="&DATE(Start!$C$6,G$3,1),Buchungen!$A$5:$A$1004,"<"&DATE(Start!$C$6,G$3+1,1))) -> 0 | H28: =IF($A28="",0,SUMIFS(Buchungen!$D$5:$D$1004,Buchungen!$B$5:$B$1004,$A28,Buchungen!$A$5:$A$1004,">="&DATE(Start!$C$6,H$3,1),Buchungen!$A$5:$A$1004,"<"&DATE(Start!$C$6,H$3+1,1))) -> 0 | I28: =IF($A28="",0,SUMIFS(Buchungen!$D$5:$D$1004,Buchungen!$B$5:$B$1004,$A28,Buchungen!$A$5:$A$1004,">="&DATE(Start!$C$6,I$3,1),Buchungen!$A$5:$A$1004,"<"&DATE(Start!$C$6,I$3+1,1))) -> 0 | J28: =IF($A28="",0,SUMIFS(Buchungen!$D$5:$D$1004,Buchungen!$B$5:$B$1004,$A28,Buchungen!$A$5:$A$1004,">="&DATE(Start!$C$6,J$3,1),Buchungen!$A$5:$A$1004,"<"&DATE(Start!$C$6,J$3+1,1))) -> 0 | ... N28: =IF($A28="",0,SUMIFS(Buchungen!$D$5:$D$1004,Buchungen!$B$5:$B$1004,$A28,Buchungen!$A$5:$A$1004,">="&DATE(Start!$C$6,N$3,1),Buchungen!$A$5:$A$1004,"<"&DATE(Start!$C$6,N$3+1,1))) -> 0 | O28: =SUM(C28:N28) -> 0 | P28: =IF($A28="","",O28/MAX(1,$B$48)) -> 0 | Q28: =IF(OR($A28="",$B28=0),"",B28*$B$48) | R28: =IF(OR($A28="",$B28=0),"",Q28-O28) | S28: =IF($A28="",-1,O28+(100-ROW())/1000000) -> 7.2e-05
... A41: =IF(Kategorien!A37="","",Kategorien!A37) | B41: =IF($A41="",0,N(Kategorien!C37)) -> 0 | C41: =IF($A41="",0,SUMIFS(Buchungen!$D$5:$D$1004,Buchungen!$B$5:$B$1004,$A41,Buchungen!$A$5:$A$1004,">="&DATE(Start!$C$6,C$3,1),Buchungen!$A$5:$A$1004,"<"&DATE(Start!$C$6,C$3+1,1))) -> 0 | D41: =IF($A41="",0,SUMIFS(Buchungen!$D$5:$D$1004,Buchungen!$B$5:$B$1004,$A41,Buchungen!$A$5:$A$1004,">="&DATE(Start!$C$6,D$3,1),Buchungen!$A$5:$A$1004,"<"&DATE(Start!$C$6,D$3+1,1))) -> 0 | E41: =IF($A41="",0,SUMIFS(Buchungen!$D$5:$D$1004,Buchungen!$B$5:$B$1004,$A41,Buchungen!$A$5:$A$1004,">="&DATE(Start!$C$6,E$3,1),Buchungen!$A$5:$A$1004,"<"&DATE(Start!$C$6,E$3+1,1))) -> 0 | F41: =IF($A41="",0,SUMIFS(Buchungen!$D$5:$D$1004,Buchungen!$B$5:$B$1004,$A41,Buchungen!$A$5:$A$1004,">="&DATE(Start!$C$6,F$3,1),Buchungen!$A$5:$A$1004,"<"&DATE(Start!$C$6,F$3+1,1))) -> 0 | G41: =IF($A41="",0,SUMIFS(Buchungen!$D$5:$D$1004,Buchungen!$B$5:$B$1004,$A41,Buchungen!$A$5:$A$1004,">="&DATE(Start!$C$6,G$3,1),Buchungen!$A$5:$A$1004,"<"&DATE(Start!$C$6,G$3+1,1))) -> 0 | H41: =IF($A41="",0,SUMIFS(Buchungen!$D$5:$D$1004,Buchungen!$B$5:$B$1004,$A41,Buchungen!$A$5:$A$1004,">="&DATE(Start!$C$6,H$3,1),Buchungen!$A$5:$A$1004,"<"&DATE(Start!$C$6,H$3+1,1))) -> 0 | I41: =IF($A41="",0,SUMIFS(Buchungen!$D$5:$D$1004,Buchungen!$B$5:$B$1004,$A41,Buchungen!$A$5:$A$1004,">="&DATE(Start!$C$6,I$3,1),Buchungen!$A$5:$A$1004,"<"&DATE(Start!$C$6,I$3+1,1))) -> 0 | J41: =IF($A41="",0,SUMIFS(Buchungen!$D$5:$D$1004,Buchungen!$B$5:$B$1004,$A41,Buchungen!$A$5:$A$1004,">="&DATE(Start!$C$6,J$3,1),Buchungen!$A$5:$A$1004,"<"&DATE(Start!$C$6,J$3+1,1))) -> 0 | ... N41: =IF($A41="",0,SUMIFS(Buchungen!$D$5:$D$1004,Buchungen!$B$5:$B$1004,$A41,Buchungen!$A$5:$A$1004,">="&DATE(Start!$C$6,N$3,1),Buchungen!$A$5:$A$1004,"<"&DATE(Start!$C$6,N$3+1,1))) -> 0 | O41: =SUM(C41:N41) -> 0 | P41: =IF($A41="","",O41/MAX(1,$B$48)) | Q41: =IF(OR($A41="",$B41=0),"",B41*$B$48) | R41: =IF(OR($A41="",$B41=0),"",Q41-O41) | S41: =IF($A41="",-1,O41+(100-ROW())/1000000) -> -1
A42: Summe Ausgaben | B42: =SUM(B17:B41) -> 0 | C42: =SUM(C17:C41) -> 0 | D42: =SUM(D17:D41) -> 0 | E42: =SUM(E17:E41) -> 0 | F42: =SUM(F17:F41) -> 0 | G42: =SUM(G17:G41) -> 0 | H42: =SUM(H17:H41) -> 0 | I42: =SUM(I17:I41) -> 0 | ... O42: =SUM(O17:O41) -> 0 | P42: =O42/MAX(1,$B$48) -> 0 | Q42: =SUM(Q17:Q41) -> 0
A44: Überschuss (Einnahmen − Ausgaben) | C44: =C14-C42 -> 2100 | D44: =D14-D42 -> 0 | E44: =E14-E42 -> 0 | F44: =F14-F42 -> 0 | G44: =G14-G42 -> 0 | H44: =H14-H42 -> 0 | I44: =I14-I42 -> 0 | J44: =J14-J42 -> 0 | ... O44: =O14-O42 -> 2100
A45: Sparquote | C45: =IF(C14=0,0,C44/C14) -> 1 | D45: =IF(D14=0,0,D44/D14) -> 0 | E45: =IF(E14=0,0,E44/E14) -> 0 | F45: =IF(F14=0,0,F44/F14) -> 0 | G45: =IF(G14=0,0,G44/G14) -> 0 | H45: =IF(H14=0,0,H44/H14) -> 0 | I45: =IF(I14=0,0,I44/I14) -> 0 | J45: =IF(J14=0,0,J44/J14) -> 0 | ... O45: =IF(O14=0,0,O44/O14) -> 1
A46: Kontostand am Monatsende | C46: =Start!$C$7+SUM($C$44:C44) -> 2100 | D46: =Start!$C$7+SUM($C$44:D44) -> 2100 | E46: =Start!$C$7+SUM($C$44:E44) -> 2100 | F46: =Start!$C$7+SUM($C$44:F44) -> 2100 | G46: =Start!$C$7+SUM($C$44:G44) -> 2100 | H46: =Start!$C$7+SUM($C$44:H44) -> 2100 | I46: =Start!$C$7+SUM($C$44:I44) -> 2100 | J46: =Start!$C$7+SUM($C$44:J44) -> 2100 | ... N46: =Start!$C$7+SUM($C$44:N44) -> 2100
A48: Monate mit Buchungen | B48: =SUMPRODUCT(--((C14:N14+C42:N42)>0)) -> 1
A49: „Ø / Monat“ und „Budget bisher“ beziehen sich auf die Monate mit Buchungen.

Sheet Sparziele
A1: Sparziele
A2: Trag dein Ziel, den Betrag und deine monatliche Sparrate ein – der Rest rechnet sich von selbst.
A4: Ziel | B4: Zielbetrag (€) | C4: Schon gespart (€) | D4: Sparrate / Monat (€) | E4: Fehlt noch (€) | F4: Fortschritt | G4: Monate bis Ziel | H4: Ziel erreicht ca.
A5: Notgroschen (Beispiel – überschreiben) | B5: 3000 | C5: 0 | D5: 100 | E5: =IF(A5="","",MAX(0,N(B5)-N(C5))) -> 3000 | F5: =IF(OR(A5="",N(B5)=0),"",MIN(1,N(C5)/B5)) -> 0 | G5: =IF(A5="","",IF(E5=0,0,IF(N(D5)<=0,"Rate fehlt",ROUNDUP(E5/D5,0)))) -> 30 | H5: =IF(ISNUMBER(G5),IF(G5=0,"erreicht!",EDATE(TODAY(),G5)),"") -> 47232
E6: =IF(A6="","",MAX(0,N(B6)-N(C6))) | F6: =IF(OR(A6="",N(B6)=0),"",MIN(1,N(C6)/B6)) | G6: =IF(A6="","",IF(E6=0,0,IF(N(D6)<=0,"Rate fehlt",ROUNDUP(E6/D6,0)))) | H6: =IF(ISNUMBER(G6),IF(G6=0,"erreicht!",EDATE(TODAY(),G6)),"")
E7: =IF(A7="","",MAX(0,N(B7)-N(C7))) | F7: =IF(OR(A7="",N(B7)=0),"",MIN(1,N(C7)/B7)) | G7: =IF(A7="","",IF(E7=0,0,IF(N(D7)<=0,"Rate fehlt",ROUNDUP(E7/D7,0)))) | H7: =IF(ISNUMBER(G7),IF(G7=0,"erreicht!",EDATE(TODAY(),G7)),"")
E8: =IF(A8="","",MAX(0,N(B8)-N(C8))) | F8: =IF(OR(A8="",N(B8)=0),"",MIN(1,N(C8)/B8)) | G8: =IF(A8="","",IF(E8=0,0,IF(N(D8)<=0,"Rate fehlt",ROUNDUP(E8/D8,0)))) | H8: =IF(ISNUMBER(G8),IF(G8=0,"erreicht!",EDATE(TODAY(),G8)),"")
E9: =IF(A9="","",MAX(0,N(B9)-N(C9))) | F9: =IF(OR(A9="",N(B9)=0),"",MIN(1,N(C9)/B9)) | G9: =IF(A9="","",IF(E9=0,0,IF(N(D9)<=0,"Rate fehlt",ROUNDUP(E9/D9,0)))) | H9: =IF(ISNUMBER(G9),IF(G9=0,"erreicht!",EDATE(TODAY(),G9)),"")
E10: =IF(A10="","",MAX(0,N(B10)-N(C10))) | F10: =IF(OR(A10="",N(B10)=0),"",MIN(1,N(C10)/B10)) | G10: =IF(A10="","",IF(E10=0,0,IF(N(D10)<=0,"Rate fehlt",ROUNDUP(E10/D10,0)))) | H10: =IF(ISNUMBER(G10),IF(G10=0,"erreicht!",EDATE(TODAY(),G10)),"")
E11: =IF(A11="","",MAX(0,N(B11)-N(C11))) | F11: =IF(OR(A11="",N(B11)=0),"",MIN(1,N(C11)/B11)) | G11: =IF(A11="","",IF(E11=0,0,IF(N(D11)<=0,"Rate fehlt",ROUNDUP(E11/D11,0)))) | H11: =IF(ISNUMBER(G11),IF(G11=0,"erreicht!",EDATE(TODAY(),G11)),"")
E12: =IF(A12="","",MAX(0,N(B12)-N(C12))) | F12: =IF(OR(A12="",N(B12)=0),"",MIN(1,N(C12)/B12)) | G12: =IF(A12="","",IF(E12=0,0,IF(N(D12)<=0,"Rate fehlt",ROUNDUP(E12/D12,0)))) | H12: =IF(ISNUMBER(G12),IF(G12=0,"erreicht!",EDATE(TODAY(),G12)),"")
E13: =IF(A13="","",MAX(0,N(B13)-N(C13))) | F13: =IF(OR(A13="",N(B13)=0),"",MIN(1,N(C13)/B13)) | G13: =IF(A13="","",IF(E13=0,0,IF(N(D13)<=0,"Rate fehlt",ROUNDUP(E13/D13,0)))) | H13: =IF(ISNUMBER(G13),IF(G13=0,"erreicht!",EDATE(TODAY(),G13)),"")
E14: =IF(A14="","",MAX(0,N(B14)-N(C14))) | F14: =IF(OR(A14="",N(B14)=0),"",MIN(1,N(C14)/B14)) | G14: =IF(A14="","",IF(E14=0,0,IF(N(D14)<=0,"Rate fehlt",ROUNDUP(E14/D14,0)))) | H14: =IF(ISNUMBER(G14),IF(G14=0,"erreicht!",EDATE(TODAY(),G14)),"")
A16: Summe | B16: =SUM(B5:B14) -> 3000 | C16: =SUM(C5:C14) -> 0 | D16: =SUM(D5:D14) -> 100 | E16: =SUM(E5:E14) -> 3000
A18: Tipp: Bau zuerst einen Notgroschen von etwa 3 Monatsausgaben auf. Richte die Sparrate als Dauerauftrag direkt nach dem Gehaltseingang ein.

Sheet Schulden
A1: Schulden-Plan
A2: Trag Restbetrag, Zinssatz und Monatsrate ein – du siehst sofort, wann du schuldenfrei bist und wie viel Zinsen du zahlst.
A4: Schuld | B4: Restbetrag (€) | C4: Zinssatz p.a. | D4: Monatsrate (€) | E4: Monate bis schuldenfrei | F4: Schuldenfrei ca. | G4: Zinsen gesamt ca. (€)
A5: Dispo (Beispiel – überschreiben) | B5: 500 | C5: 0.129 | D5: 50 | E5: =IF(A5="","",IF(N(B5)<=0,0,IF(N(D5)<=0,"Rate fehlt",IF(N(C5)=0,ROUNDUP(B5/D5,0),IF(D5<=B5*C5/12,"Rate zu niedrig",ROUNDUP(NPER(C5/12,-D5,B5),0)))))) -> 11 | F5: =IF(ISNUMBER(E5),IF(E5=0,"schuldenfrei!",EDATE(TODAY(),E5)),"") -> 46654 | G5: =IF(ISNUMBER(E5),IF(OR(E5=0,N(C5)=0),0,D5*NPER(C5/12,-D5,B5)-B5),"") -> 31.809154
E6: =IF(A6="","",IF(N(B6)<=0,0,IF(N(D6)<=0,"Rate fehlt",IF(N(C6)=0,ROUNDUP(B6/D6,0),IF(D6<=B6*C6/12,"Rate zu niedrig",ROUNDUP(NPER(C6/12,-D6,B6),0)))))) | F6: =IF(ISNUMBER(E6),IF(E6=0,"schuldenfrei!",EDATE(TODAY(),E6)),"") | G6: =IF(ISNUMBER(E6),IF(OR(E6=0,N(C6)=0),0,D6*NPER(C6/12,-D6,B6)-B6),"")
E7: =IF(A7="","",IF(N(B7)<=0,0,IF(N(D7)<=0,"Rate fehlt",IF(N(C7)=0,ROUNDUP(B7/D7,0),IF(D7<=B7*C7/12,"Rate zu niedrig",ROUNDUP(NPER(C7/12,-D7,B7),0)))))) | F7: =IF(ISNUMBER(E7),IF(E7=0,"schuldenfrei!",EDATE(TODAY(),E7)),"") | G7: =IF(ISNUMBER(E7),IF(OR(E7=0,N(C7)=0),0,D7*NPER(C7/12,-D7,B7)-B7),"")
E8: =IF(A8="","",IF(N(B8)<=0,0,IF(N(D8)<=0,"Rate fehlt",IF(N(C8)=0,ROUNDUP(B8/D8,0),IF(D8<=B8*C8/12,"Rate zu niedrig",ROUNDUP(NPER(C8/12,-D8,B8),0)))))) | F8: =IF(ISNUMBER(E8),IF(E8=0,"schuldenfrei!",EDATE(TODAY(),E8)),"") | G8: =IF(ISNUMBER(E8),IF(OR(E8=0,N(C8)=0),0,D8*NPER(C8/12,-D8,B8)-B8),"")
E9: =IF(A9="","",IF(N(B9)<=0,0,IF(N(D9)<=0,"Rate fehlt",IF(N(C9)=0,ROUNDUP(B9/D9,0),IF(D9<=B9*C9/12,"Rate zu niedrig",ROUNDUP(NPER(C9/12,-D9,B9),0)))))) | F9: =IF(ISNUMBER(E9),IF(E9=0,"schuldenfrei!",EDATE(TODAY(),E9)),"") | G9: =IF(ISNUMBER(E9),IF(OR(E9=0,N(C9)=0),0,D9*NPER(C9/12,-D9,B9)-B9),"")
E10: =IF(A10="","",IF(N(B10)<=0,0,IF(N(D10)<=0,"Rate fehlt",IF(N(C10)=0,ROUNDUP(B10/D10,0),IF(D10<=B10*C10/12,"Rate zu niedrig",ROUNDUP(NPER(C10/12,-D10,B10),0)))))) | F10: =IF(ISNUMBER(E10),IF(E10=0,"schuldenfrei!",EDATE(TODAY(),E10)),"") | G10: =IF(ISNUMBER(E10),IF(OR(E10=0,N(C10)=0),0,D10*NPER(C10/12,-D10,B10)-B10),"")
